Workbook
Name TRANSMUTATION_TABLE: 'DO NOT DELETE'!$G$2:$J$42

Sheet SCIENCE _Q1
A1: Class Record
A3: (Pursuant to Deped Order 8 series of 2015)
C4: REGION | G4: NCR | U4: DIVISION | V4: PARAÑAQUE | Z4: DISTRICT | AH4: VII
B6: SCHOOL NAME | G6: STO. NIÑO ELEMENTARY SCHOOL | Z6: SCHOOL ID | AH6: 136765 | AK6: SCHOOL YEAR | AN6: 2025 - 2026
A8: FIRST QUARTER | F8: GRADE & SECTION: | O8: V-MOLAVE | W8: TEACHER: | Y8: MRS. JANE DOE | AJ8: SUBJECT: | AL8: SCIENCE 5
B9: LEARNERS' NAMES | F9: WRITTEN WORKS (40%) | Y9: PERFORMANCE TASKS (40%) | AM9: QUARTERLY ASSESSMENT (20%) | AP9: Initial Grade | AQ9: Quarterly Grade
F10: SEATWORK | U10: Notebook | Y10: GROUP ACTIVITY | AI10: Recitation
F11: (Let's Recall, Let's Apply, Let's Analyze, Let's Try) | Y11: Let's Create | AM11: Periodic Test | AX11: 60-69 | AY11: 78
F12: 1 | G12: 2 | H12: 3 | I12: 4 | J12: 5 | K12: 6 | L12: 7 | M12: 8 | N12: 9 | O12: 10 | P12: 11 | Q12: 12 | R12: 13 | S12: 14 | T12: 15 | U12: 1 | V12: Total | W12: PS | X12: WS | Y12: 1 | Z12: 2 | AA12: 3 | AB12: 4 | AC12: 5 | AD12: 6 | AE12: 7 | AF12: 8 | AG12: 9 | AH12: 10 | AI12: 1 | AJ12: Total | AK12: PS | AL12: WS | AM12: 1 | AN12: PS | AO12: WS | AX12: 70-74 | AY12: 79
B13: HIGHEST POSSIBLE SCORE | V13: =IF(COUNT($F13:$U13)=0,"",SUM($F13:$U13)) | W13: 100 | X13: 0.4 | AJ13: =IF(COUNT($Y13:$AI13)=0,"",SUM($Y13:$AI13)) | AK13: 100 | AL13: 0.4 | AN13: 100 | AO13: 0.2 | AX13: 75-79 | AY13: 80
B14: MALE | AX14: 80-84 | AY14: 85
A15: 1 | V15: =IF(COUNT($F15:$U15)=0,"",SUM($F15:$U15)) | W15: =IF(ISERROR(IF($V15="","",ROUND(($V15/$V$13)*$W$13,2))),"",IF($V15="","",ROUND(($V15/$V$13)*$W$13,2))) | X15: =IF($W15="","",ROUND($W15*$X$13,2)) | AJ15: =IF(COUNT($Y15:$AI15)=0,"",SUM($Y15:$AI15)) | AK15: =IF(ISERROR(IF($AJ15="","",ROUND(($AJ15/$AJ$13)*$AK$13,2))),"",IF($AJ15="","",ROUND(($AJ15/$AJ$13)*$AK$13,2))) | AL15: =IF($AK15="","",ROUND($AK15*$AL$13,2)) | AN15: =IF(ISERROR(IF($AM15="","",ROUND(($AM15/$AM$13)*$AN$13,2))),"",IF($AM15="","",ROUND(($AM15/$AM$13)*$AN$13,2))) | AO15: =IF($AN15="","",ROUND($AN15*$AO$13,2)) | AP15: =IF(ISERROR(IF($AM15="","",ROUND(SUM($X15,$AL15,$AO15),2))),"",IF($AM15="","",ROUND(SUM($X15,$AL15,$AO15),2))) | AQ15: =IF(ISERROR(IF($AM15="","",VLOOKUP(AP15,TRANSMUTATION_TABLE,4,TRUE))),"",IF($AM15="","",VLOOKUP(AP15,TRANSMUTATION_TABLE,4,TRUE))) | AX15: 85-88 | AY15: 89
A16: 2 | V16: =IF(COUNT($F16:$U16)=0,"",SUM($F16:$U16)) | W16: =IF(ISERROR(IF($V16="","",ROUND(($V16/$V$13)*$W$13,2))),"",IF($V16="","",ROUND(($V16/$V$13)*$W$13,2))) | X16: =IF($W16="","",ROUND($W16*$X$13,2)) | AJ16: =IF(COUNT($Y16:$AI16)=0,"",SUM($Y16:$AI16)) | AK16: =IF(ISERROR(IF($AJ16="","",ROUND(($AJ16/$AJ$13)*$AK$13,2))),"",IF($AJ16="","",ROUND(($AJ16/$AJ$13)*$AK$13,2))) | AL16: =IF($AK16="","",ROUND($AK16*$AL$13,2)) | AN16: =IF(ISERROR(IF($AM16="","",ROUND(($AM16/$AM$13)*$AN$13,2))),"",IF($AM16="","",ROUND(($AM16/$AM$13)*$AN$13,2))) | AO16: =IF($AN16="","",ROUND($AN16*$AO$13,2)) | AP16: =IF(ISERROR(IF($AM16="","",ROUND(SUM($X16,$AL16,$AO16),2))),"",IF($AM16="","",ROUND(SUM($X16,$AL16,$AO16),2))) | AQ16: =IF(ISERROR(IF($AM16="","",VLOOKUP(AP16,TRANSMUTATION_TABLE,4,TRUE))),"",IF($AM16="","",VLOOKUP(AP16,TRANSMUTATION_TABLE,4,TRUE))) | AX16: 89-91 | AY16: 92
A17: 3 | V17: =IF(COUNT($F17:$U17)=0,"",SUM($F17:$U17)) | W17: =IF(ISERROR(IF($V17="","",ROUND(($V17/$V$13)*$W$13,2))),"",IF($V17="","",ROUND(($V17/$V$13)*$W$13,2))) | X17: =IF($W17="","",ROUND($W17*$X$13,2)) | AJ17: =IF(COUNT($Y17:$AI17)=0,"",SUM($Y17:$AI17)) | AK17: =IF(ISERROR(IF($AJ17="","",ROUND(($AJ17/$AJ$13)*$AK$13,2))),"",IF($AJ17="","",ROUND(($AJ17/$AJ$13)*$AK$13,2))) | AL17: =IF($AK17="","",ROUND($AK17*$AL$13,2)) | AN17: =IF(ISERROR(IF($AM17="","",ROUND(($AM17/$AM$13)*$AN$13,2))),"",IF($AM17="","",ROUND(($AM17/$AM$13)*$AN$13,2))) | AO17: =IF($AN17="","",ROUND($AN17*$AO$13,2)) | AP17: =IF(ISERROR(IF($AM17="","",ROUND(SUM($X17,$AL17,$AO17),2))),"",IF($AM17="","",ROUND(SUM($X17,$AL17,$AO17),2))) | AQ17: =IF(ISERROR(IF($AM17="","",VLOOKUP(AP17,TRANSMUTATION_TABLE,4,TRUE))),"",IF($AM17="","",VLOOKUP(AP17,TRANSMUTATION_TABLE,4,TRUE)))
A18: 4 | V18: =IF(COUNT($F18:$U18)=0,"",SUM($F18:$U18)) | W18: =IF(ISERROR(IF($V18="","",ROUND(($V18/$V$13)*$W$13,2))),"",IF($V18="","",ROUND(($V18/$V$13)*$W$13,2))) | X18: =IF($W18="","",ROUND($W18*$X$13,2)) | AJ18: =IF(COUNT($Y18:$AI18)=0,"",SUM($Y18:$AI18)) | AK18: =IF(ISERROR(IF($AJ18="","",ROUND(($AJ18/$AJ$13)*$AK$13,2))),"",IF($AJ18="","",ROUND(($AJ18/$AJ$13)*$AK$13,2))) | AL18: =IF($AK18="","",ROUND($AK18*$AL$13,2)) | AN18: =IF(ISERROR(IF($AM18="","",ROUND(($AM18/$AM$13)*$AN$13,2))),"",IF($AM18="","",ROUND(($AM18/$AM$13)*$AN$13,2))) | AO18: =IF($AN18="","",ROUND($AN18*$AO$13,2)) | AP18: =IF(ISERROR(IF($AM18="","",ROUND(SUM($X18,$AL18,$AO18),2))),"",IF($AM18="","",ROUND(SUM($X18,$AL18,$AO18),2))) | AQ18: =IF(ISERROR(IF($AM18="","",VLOOKUP(AP18,TRANSMUTATION_TABLE,4,TRUE))),"",IF($AM18="","",VLOOKUP(AP18,TRANSMUTATION_TABLE,4,TRUE)))
A19: 5 | V19: =IF(COUNT($F19:$U19)=0,"",SUM($F19:$U19)) | W19: =IF(ISERROR(IF($V19="","",ROUND(($V19/$V$13)*$W$13,2))),"",IF($V19="","",ROUND(($V19/$V$13)*$W$13,2))) | X19: =IF($W19="","",ROUND($W19*$X$13,2)) | AJ19: =IF(COUNT($Y19:$AI19)=0,"",SUM($Y19:$AI19)) | AK19: =IF(ISERROR(IF($AJ19="","",ROUND(($AJ19/$AJ$13)*$AK$13,2))),"",IF($AJ19="","",ROUND(($AJ19/$AJ$13)*$AK$13,2))) | AL19: =IF($AK19="","",ROUND($AK19*$AL$13,2)) | AN19: =IF(ISERROR(IF($AM19="","",ROUND(($AM19/$AM$13)*$AN$13,2))),"",IF($AM19="","",ROUND(($AM19/$AM$13)*$AN$13,2))) | AO19: =IF($AN19="","",ROUND($AN19*$AO$13,2)) | AP19: =IF(ISERROR(IF($AM19="","",ROUND(SUM($X19,$AL19,$AO19),2))),"",IF($AM19="","",ROUND(SUM($X19,$AL19,$AO19),2))) | AQ19: =IF(ISERROR(IF($AM19="","",VLOOKUP(AP19,TRANSMUTATION_TABLE,4,TRUE))),"",IF($AM19="","",VLOOKUP(AP19,TRANSMUTATION_TABLE,4,TRUE)))
A20: 6 | V20: =IF(COUNT($F20:$U20)=0,"",SUM($F20:$U20)) | W20: =IF(ISERROR(IF($V20="","",ROUND(($V20/$V$13)*$W$13,2))),"",IF($V20="","",ROUND(($V20/$V$13)*$W$13,2))) | X20: =IF($W20="","",ROUND($W20*$X$13,2)) | AJ20: =IF(COUNT($Y20:$AI20)=0,"",SUM($Y20:$AI20)) | AK20: =IF(ISERROR(IF($AJ20="","",ROUND(($AJ20/$AJ$13)*$AK$13,2))),"",IF($AJ20="","",ROUND(($AJ20/$AJ$13)*$AK$13,2))) | AL20: =IF($AK20="","",ROUND($AK20*$AL$13,2)) | AN20: =IF(ISERROR(IF($AM20="","",ROUND(($AM20/$AM$13)*$AN$13,2))),"",IF($AM20="","",ROUND(($AM20/$AM$13)*$AN$13,2))) | AO20: =IF($AN20="","",ROUND($AN20*$AO$13,2)) | AP20: =IF(ISERROR(IF($AM20="","",ROUND(SUM($X20,$AL20,$AO20),2))),"",IF($AM20="","",ROUND(SUM($X20,$AL20,$AO20),2))) | AQ20: =IF(ISERROR(IF($AM20="","",VLOOKUP(AP20,TRANSMUTATION_TABLE,4,TRUE))),"",IF($AM20="","",VLOOKUP(AP20,TRANSMUTATION_TABLE,4,TRUE)))
A21: 7 | V21: =IF(COUNT($F21:$U21)=0,"",SUM($F21:$U21)) | W21: =IF(ISERROR(IF($V21="","",ROUND(($V21/$V$13)*$W$13,2))),"",IF($V21="","",ROUND(($V21/$V$13)*$W$13,2))) | X21: =IF($W21="","",ROUND($W21*$X$13,2)) | AJ21: =IF(COUNT($Y21:$AI21)=0,"",SUM($Y21:$AI21)) | AK21: =IF(ISERROR(IF($AJ21="","",ROUND(($AJ21/$AJ$13)*$AK$13,2))),"",IF($AJ21="","",ROUND(($AJ21/$AJ$13)*$AK$13,2))) | AL21: =IF($AK21="","",ROUND($AK21*$AL$13,2)) | AN21: =IF(ISERROR(IF($AM21="","",ROUND(($AM21/$AM$13)*$AN$13,2))),"",IF($AM21="","",ROUND(($AM21/$AM$13)*$AN$13,2))) | AO21: =IF($AN21="","",ROUND($AN21*$AO$13,2)) | AP21: =IF(ISERROR(IF($AM21="","",ROUND(SUM($X21,$AL21,$AO21),2))),"",IF($AM21="","",ROUND(SUM($X21,$AL21,$AO21),2))) | AQ21: =IF(ISERROR(IF($AM21="","",VLOOKUP(AP21,TRANSMUTATION_TABLE,4,TRUE))),"",IF($AM21="","",VLOOKUP(AP21,TRANSMUTATION_TABLE,4,TRUE)))
A22: 8 | V22: =IF(COUNT($F22:$U22)=0,"",SUM($F22:$U22)) | W22: =IF(ISERROR(IF($V22="","",ROUND(($V22/$V$13)*$W$13,2))),"",IF($V22="","",ROUND(($V22/$V$13)*$W$13,2))) | X22: =IF($W22="","",ROUND($W22*$X$13,2)) | AJ22: =IF(COUNT($Y22:$AI22)=0,"",SUM($Y22:$AI22)) | AK22: =IF(ISERROR(IF($AJ22="","",ROUND(($AJ22/$AJ$13)*$AK$13,2))),"",IF($AJ22="","",ROUND(($AJ22/$AJ$13)*$AK$13,2))) | AL22: =IF($AK22="","",ROUND($AK22*$AL$13,2)) | AN22: =IF(ISERROR(IF($AM22="","",ROUND(($AM22/$AM$13)*$AN$13,2))),"",IF($AM22="","",ROUND(($AM22/$AM$13)*$AN$13,2))) | AO22: =IF($AN22="","",ROUND($AN22*$AO$13,2)) | AP22: =IF(ISERROR(IF($AM22="","",ROUND(SUM($X22,$AL22,$AO22),2))),"",IF($AM22="","",ROUND(SUM($X22,$AL22,$AO22),2))) | AQ22: =IF(ISERROR(IF($AM22="","",VLOOKUP(AP22,TRANSMUTATION_TABLE,4,TRUE))),"",IF($AM22="","",VLOOKUP(AP22,TRANSMUTATION_TABLE,4,TRUE)))
A23: 9 | V23: =IF(COUNT($F23:$U23)=0,"",SUM($F23:$U23)) | W23: =IF(ISERROR(IF($V23="","",ROUND(($V23/$V$13)*$W$13,2))),"",IF($V23="","",ROUND(($V23/$V$13)*$W$13,2))) | X23: =IF($W23="","",ROUND($W23*$X$13,2)) | AJ23: =IF(COUNT($Y23:$AI23)=0,"",SUM($Y23:$AI23)) | AK23: =IF(ISERROR(IF($AJ23="","",ROUND(($AJ23/$AJ$13)*$AK$13,2))),"",IF($AJ23="","",ROUND(($AJ23/$AJ$13)*$AK$13,2))) | AL23: =IF($AK23="","",ROUND($AK23*$AL$13,2)) | AN23: =IF(ISERROR(IF($AM23="","",ROUND(($AM23/$AM$13)*$AN$13,2))),"",IF($AM23="","",ROUND(($AM23/$AM$13)*$AN$13,2))) | AO23: =IF($AN23="","",ROUND($AN23*$AO$13,2)) | AP23: =IF(ISERROR(IF($AM23="","",ROUND(SUM($X23,$AL23,$AO23),2))),"",IF($AM23="","",ROUND(SUM($X23,$AL23,$AO23),2))) | AQ23: =IF(ISERROR(IF($AM23="","",VLOOKUP(AP23,TRANSMUTATION_TABLE,4,TRUE))),"",IF($AM23="","",VLOOKUP(AP23,TRANSMUTATION_TABLE,4,TRUE)))
A24: 10 | V24: =IF(COUNT($F24:$U24)=0,"",SUM($F24:$U24)) | W24: =IF(ISERROR(IF($V24="","",ROUND(($V24/$V$13)*$W$13,2))),"",IF($V24="","",ROUND(($V24/$V$13)*$W$13,2))) | X24: =IF($W24="","",ROUND($W24*$X$13,2)) | AJ24: =IF(COUNT($Y24:$AI24)=0,"",SUM($Y24:$AI24)) | AK24: =IF(ISERROR(IF($AJ24="","",ROUND(($AJ24/$AJ$13)*$AK$13,2))),"",IF($AJ24="","",ROUND(($AJ24/$AJ$13)*$AK$13,2))) | AL24: =IF($AK24="","",ROUND($AK24*$AL$13,2)) | AN24: =IF(ISERROR(IF($AM24="","",ROUND(($AM24/$AM$13)*$AN$13,2))),"",IF($AM24="","",ROUND(($AM24/$AM$13)*$AN$13,2))) | AO24: =IF($AN24="","",ROUND($AN24*$AO$13,2)) | AP24: =IF(ISERROR(IF($AM24="","",ROUND(SUM($X24,$AL24,$AO24),2))),"",IF($AM24="","",ROUND(SUM($X24,$AL24,$AO24),2))) | AQ24: =IF(ISERROR(IF($AM24="","",VLOOKUP(AP24,TRANSMUTATION_TABLE,4,TRUE))),"",IF($AM24="","",VLOOKUP(AP24,TRANSMUTATION_TABLE,4,TRUE)))
A25: 11 | V25: =IF(COUNT($F25:$U25)=0,"",SUM($F25:$U25)) | W25: =IF(ISERROR(IF($V25="","",ROUND(($V25/$V$13)*$W$13,2))),"",IF($V25="","",ROUND(($V25/$V$13)*$W$13,2))) | X25: =IF($W25="","",ROUND($W25*$X$13,2)) | AJ25: =IF(COUNT($Y25:$AI25)=0,"",SUM($Y25:$AI25)) | AK25: =IF(ISERROR(IF($AJ25="","",ROUND(($AJ25/$AJ$13)*$AK$13,2))),"",IF($AJ25="","",ROUND(($AJ25/$AJ$13)*$AK$13,2))) | AL25: =IF($AK25="","",ROUND($AK25*$AL$13,2)) | AN25: =IF(ISERROR(IF($AM25="","",ROUND(($AM25/$AM$13)*$AN$13,2))),"",IF($AM25="","",ROUND(($AM25/$AM$13)*$AN$13,2))) | AO25: =IF($AN25="","",ROUND($AN25*$AO$13,2)) | AP25: =IF(ISERROR(IF($AM25="","",ROUND(SUM($X25,$AL25,$AO25),2))),"",IF($AM25="","",ROUND(SUM($X25,$AL25,$AO25),2))) | AQ25: =IF(ISERROR(IF($AM25="","",VLOOKUP(AP25,TRANSMUTATION_TABLE,4,TRUE))),"",IF($AM25="","",VLOOKUP(AP25,TRANSMUTATION_TABLE,4,TRUE)))
A26: 12 | V26: =IF(COUNT($F26:$U26)=0,"",SUM($F26:$U26)) | W26: =IF(ISERROR(IF($V26="","",ROUND(($V26/$V$13)*$W$13,2))),"",IF($V26="","",ROUND(($V26/$V$13)*$W$13,2))) | X26: =IF($W26="","",ROUND($W26*$X$13,2)) | AJ26: =IF(COUNT($Y26:$AI26)=0,"",SUM($Y26:$AI26)) | AK26: =IF(ISERROR(IF($AJ26="","",ROUND(($AJ26/$AJ$13)*$AK$13,2))),"",IF($AJ26="","",ROUND(($AJ26/$AJ$13)*$AK$13,2))) | AL26: =IF($AK26="","",ROUND($AK26*$AL$13,2)) | AN26: =IF(ISERROR(IF($AM26="","",ROUND(($AM26/$AM$13)*$AN$13,2))),"",IF($AM26="","",ROUND(($AM26/$AM$13)*$AN$13,2))) | AO26: =IF($AN26="","",ROUND($AN26*$AO$13,2)) | AP26: =IF(ISERROR(IF($AM26="","",ROUND(SUM($X26,$AL26,$AO26),2))),"",IF($AM26="","",ROUND(SUM($X26,$AL26,$AO26),2))) | AQ26: =IF(ISERROR(IF($AM26="","",VLOOKUP(AP26,TRANSMUTATION_TABLE,4,TRUE))),"",IF($AM26="","",VLOOKUP(AP26,TRANSMUTATION_TABLE,4,TRUE)))
A27: 13 | V27: =IF(COUNT($F27:$U27)=0,"",SUM($F27:$U27)) | W27: =IF(ISERROR(IF($V27="","",ROUND(($V27/$V$13)*$W$13,2))),"",IF($V27="","",ROUND(($V27/$V$13)*$W$13,2))) | X27: =IF($W27="","",ROUND($W27*$X$13,2)) | AJ27: =IF(COUNT($Y27:$AI27)=0,"",SUM($Y27:$AI27)) | AK27: =IF(ISERROR(IF($AJ27="","",ROUND(($AJ27/$AJ$13)*$AK$13,2))),"",IF($AJ27="","",ROUND(($AJ27/$AJ$13)*$AK$13,2))) | AL27: =IF($AK27="","",ROUND($AK27*$AL$13,2)) | AN27: =IF(ISERROR(IF($AM27="","",ROUND(($AM27/$AM$13)*$AN$13,2))),"",IF($AM27="","",ROUND(($AM27/$AM$13)*$AN$13,2))) | AO27: =IF($AN27="","",ROUND($AN27*$AO$13,2)) | AP27: =IF(ISERROR(IF($AM27="","",ROUND(SUM($X27,$AL27,$AO27),2))),"",IF($AM27="","",ROUND(SUM($X27,$AL27,$AO27),2))) | AQ27: =IF(ISERROR(IF($AM27="","",VLOOKUP(AP27,TRANSMUTATION_TABLE,4,TRUE))),"",IF($AM27="","",VLOOKUP(AP27,TRANSMUTATION_TABLE,4,TRUE)))
A28: 14 | V28: =IF(COUNT($F28:$U28)=0,"",SUM($F28:$U28)) | W28: =IF(ISERROR(IF($V28="","",ROUND(($V28/$V$13)*$W$13,2))),"",IF($V28="","",ROUND(($V28/$V$13)*$W$13,2))) | X28: =IF($W28="","",ROUND($W28*$X$13,2)) | AJ28: =IF(COUNT($Y28:$AI28)=0,"",SUM($Y28:$AI28)) | AK28: =IF(ISERROR(IF($AJ28="","",ROUND(($AJ28/$AJ$13)*$AK$13,2))),"",IF($AJ28="","",ROUND(($AJ28/$AJ$13)*$AK$13,2))) | AL28: =IF($AK28="","",ROUND($AK28*$AL$13,2)) | AN28: =IF(ISERROR(IF($AM28="","",ROUND(($AM28/$AM$13)*$AN$13,2))),"",IF($AM28="","",ROUND(($AM28/$AM$13)*$AN$13,2))) | AO28: =IF($AN28="","",ROUND($AN28*$AO$13,2)) | AP28: =IF(ISERROR(IF($AM28="","",ROUND(SUM($X28,$AL28,$AO28),2))),"",IF($AM28="","",ROUND(SUM($X28,$AL28,$AO28),2))) | AQ28: =IF(ISERROR(IF($AM28="","",VLOOKUP(AP28,TRANSMUTATION_TABLE,4,TRUE))),"",IF($AM28="","",VLOOKUP(AP28,TRANSMUTATION_TABLE,4,TRUE)))
... A36: 22 | V36: =IF(COUNT($F36:$U36)=0,"",SUM($F36:$U36)) | W36: =IF(ISERROR(IF($V36="","",ROUND(($V36/$V$13)*$W$13,2))),"",IF($V36="","",ROUND(($V36/$V$13)*$W$13,2))) | X36: =IF($W36="","",ROUND($W36*$X$13,2)) | AJ36: =IF(COUNT($Y36:$AI36)=0,"",SUM($Y36:$AI36)) | AK36: =IF(ISERROR(IF($AJ36="","",ROUND(($AJ36/$AJ$13)*$AK$13,2))),"",IF($AJ36="","",ROUND(($AJ36/$AJ$13)*$AK$13,2))) | AL36: =IF($AK36="","",ROUND($AK36*$AL$13,2)) | AN36: =IF(ISERROR(IF($AM36="","",ROUND(($AM36/$AM$13)*$AN$13,2))),"",IF($AM36="","",ROUND(($AM36/$AM$13)*$AN$13,2))) | AO36: =IF($AN36="","",ROUND($AN36*$AO$13,2)) | AP36: =IF(ISERROR(IF($AM36="","",ROUND(SUM($X36,$AL36,$AO36),2))),"",IF($AM36="","",ROUND(SUM($X36,$AL36,$AO36),2))) | AQ36: =IF(ISERROR(IF($AM36="","",VLOOKUP(AP36,TRANSMUTATION_TABLE,4,TRUE))),"",IF($AM36="","",VLOOKUP(AP36,TRANSMUTATION_TABLE,4,TRUE)))
AQ37: =IF(ISERROR(IF($AM37="","",VLOOKUP(AP37,TRANSMUTATION_TABLE,4,TRUE))),"",IF($AM37="","",VLOOKUP(AP37,TRANSMUTATION_TABLE,4,TRUE)))
V38: =IF(COUNT($F38:$U38)=0,"",SUM($F38:$U38)) | W38: =IF(ISERROR(IF($V38="","",ROUND(($V38/$V$13)*$W$13,2))),"",IF($V38="","",ROUND(($V38/$V$13)*$W$13,2))) | X38: =IF($W38="","",ROUND($W38*$X$13,2)) | AJ38: =IF(COUNT($Y38:$AI38)=0,"",SUM($Y38:$AI38)) | AK38: =IF(ISERROR(IF($AJ38="","",ROUND(($AJ38/$AJ$13)*$AK$13,2))),"",IF($AJ38="","",ROUND(($AJ38/$AJ$13)*$AK$13,2))) | AL38: =IF($AK38="","",ROUND($AK38*$AL$13,2)) | AN38: =IF(ISERROR(IF($AM38="","",ROUND(($AM38/$AM$13)*$AN$13,2))),"",IF($AM38="","",ROUND(($AM38/$AM$13)*$AN$13,2))) | AO38: =IF($AN38="","",ROUND($AN38*$AO$13,2)) | AP38: =IF(ISERROR(IF($AM38="","",ROUND(SUM($X38,$AL38,$AO38),2))),"",IF($AM38="","",ROUND(SUM($X38,$AL38,$AO38),2))) | AQ38: =IF(ISERROR(IF($AM38="","",VLOOKUP(AP38,TRANSMUTATION_TABLE,4,TRUE))),"",IF($AM38="","",VLOOKUP(AP38,TRANSMUTATION_TABLE,4,TRUE)))
V39: =IF(COUNT($F39:$U39)=0,"",SUM($F39:$U39)) | W39: =IF(ISERROR(IF($V39="","",ROUND(($V39/$V$13)*$W$13,2))),"",IF($V39="","",ROUND(($V39/$V$13)*$W$13,2))) | X39: =IF($W39="","",ROUND($W39*$X$13,2)) | AJ39: =IF(COUNT($Y39:$AI39)=0,"",SUM($Y39:$AI39)) | AK39: =IF(ISERROR(IF($AJ39="","",ROUND(($AJ39/$AJ$13)*$AK$13,2))),"",IF($AJ39="","",ROUND(($AJ39/$AJ$13)*$AK$13,2))) | AL39: =IF($AK39="","",ROUND($AK39*$AL$13,2)) | AN39: =IF(ISERROR(IF($AM39="","",ROUND(($AM39/$AM$13)*$AN$13,2))),"",IF($AM39="","",ROUND(($AM39/$AM$13)*$AN$13,2))) | AO39: =IF($AN39="","",ROUND($AN39*$AO$13,2)) | AP39: =IF(ISERROR(IF($AM39="","",ROUND(SUM($X39,$AL39,$AO39),2))),"",IF($AM39="","",ROUND(SUM($X39,$AL39,$AO39),2))) | AQ39: =IF(ISERROR(IF($AM39="","",VLOOKUP(AP39,TRANSMUTATION_TABLE,4,TRUE))),"",IF($AM39="","",VLOOKUP(AP39,TRANSMUTATION_TABLE,4,TRUE)))
V40: =IF(COUNT($F40:$U40)=0,"",SUM($F40:$U40)) | W40: =IF(ISERROR(IF($V40="","",ROUND(($V40/$V$13)*$W$13,2))),"",IF($V40="","",ROUND(($V40/$V$13)*$W$13,2))) | X40: =IF($W40="","",ROUND($W40*$X$13,2)) | AJ40: =IF(COUNT($Y40:$AI40)=0,"",SUM($Y40:$AI40)) | AK40: =IF(ISERROR(IF($AJ40="","",ROUND(($AJ40/$AJ$13)*$AK$13,2))),"",IF($AJ40="","",ROUND(($AJ40/$AJ$13)*$AK$13,2))) | AL40: =IF($AK40="","",ROUND($AK40*$AL$13,2)) | AN40: =IF(ISERROR(IF($AM40="","",ROUND(($AM40/$AM$13)*$AN$13,2))),"",IF($AM40="","",ROUND(($AM40/$AM$13)*$AN$13,2))) | AO40: =IF($AN40="","",ROUND($AN40*$AO$13,2)) | AP40: =IF(ISERROR(IF($AM40="","",ROUND(SUM($X40,$AL40,$AO40),2))),"",IF($AM40="","",ROUND(SUM($X40,$AL40,$AO40),2))) | AQ40: =IF(ISERROR(IF($AM40="","",VLOOKUP(AP40,TRANSMUTATION_TABLE,4,TRUE))),"",IF($AM40="","",VLOOKUP(AP40,TRANSMUTATION_TABLE,4,TRUE)))
V41: =IF(COUNT($F41:$U41)=0,"",SUM($F41:$U41)) | W41: =IF(ISERROR(IF($V41="","",ROUND(($V41/$V$13)*$W$13,2))),"",IF($V41="","",ROUND(($V41/$V$13)*$W$13,2))) | X41: =IF($W41="","",ROUND($W41*$X$13,2)) | AJ41: =IF(COUNT($Y41:$AI41)=0,"",SUM($Y41:$AI41)) | AK41: =IF(ISERROR(IF($AJ41="","",ROUND(($AJ41/$AJ$13)*$AK$13,2))),"",IF($AJ41="","",ROUND(($AJ41/$AJ$13)*$AK$13,2))) | AL41: =IF($AK41="","",ROUND($AK41*$AL$13,2)) | AN41: =IF(ISERROR(IF($AM41="","",ROUND(($AM41/$AM$13)*$AN$13,2))),"",IF($AM41="","",ROUND(($AM41/$AM$13)*$AN$13,2))) | AO41: =IF($AN41="","",ROUND($AN41*$AO$13,2)) | AP41: =IF(ISERROR(IF($AM41="","",ROUND(SUM($X41,$AL41,$AO41),2))),"",IF($AM41="","",ROUND(SUM($X41,$AL41,$AO41),2))) | AQ41: =IF(ISERROR(IF($AM41="","",VLOOKUP(AP41,TRANSMUTATION_TABLE,4,TRUE))),"",IF($AM41="","",VLOOKUP(AP41,TRANSMUTATION_TABLE,4,TRUE)))
V42: =IF(COUNT($F42:$U42)=0,"",SUM($F42:$U42)) | W42: =IF(ISERROR(IF($V42="","",ROUND(($V42/$V$13)*$W$13,2))),"",IF($V42="","",ROUND(($V42/$V$13)*$W$13,2))) | X42: =IF($W42="","",ROUND($W42*$X$13,2)) | AJ42: =IF(COUNT($Y42:$AI42)=0,"",SUM($Y42:$AI42)) | AK42: =IF(ISERROR(IF($AJ42="","",ROUND(($AJ42/$AJ$13)*$AK$13,2))),"",IF($AJ42="","",ROUND(($AJ42/$AJ$13)*$AK$13,2))) | AL42: =IF($AK42="","",ROUND($AK42*$AL$13,2)) | AN42: =IF(ISERROR(IF($AM42="","",ROUND(($AM42/$AM$13)*$AN$13,2))),"",IF($AM42="","",ROUND(($AM42/$AM$13)*$AN$13,2))) | AO42: =IF($AN42="","",ROUND($AN42*$AO$13,2)) | AP42: =IF(ISERROR(IF($AM42="","",ROUND(SUM($X42,$AL42,$AO42),2))),"",IF($AM42="","",ROUND(SUM($X42,$AL42,$AO42),2))) | AQ42: =IF(ISERROR(IF($AM42="","",VLOOKUP(AP42,TRANSMUTATION_TABLE,4,TRUE))),"",IF($AM42="","",VLOOKUP(AP42,TRANSMUTATION_TABLE,4,TRUE)))
V43: =IF(COUNT($F43:$U43)=0,"",SUM($F43:$U43)) | W43: =IF(ISERROR(IF($V43="","",ROUND(($V43/$V$13)*$W$13,2))),"",IF($V43="","",ROUND(($V43/$V$13)*$W$13,2))) | X43: =IF($W43="","",ROUND($W43*$X$13,2)) | AJ43: =IF(COUNT($Y43:$AI43)=0,"",SUM($Y43:$AI43)) | AK43: =IF(ISERROR(IF($AJ43="","",ROUND(($AJ43/$AJ$13)*$AK$13,2))),"",IF($AJ43="","",ROUND(($AJ43/$AJ$13)*$AK$13,2))) | AL43: =IF($AK43="","",ROUND($AK43*$AL$13,2)) | AN43: =IF(ISERROR(IF($AM43="","",ROUND(($AM43/$AM$13)*$AN$13,2))),"",IF($AM43="","",ROUND(($AM43/$AM$13)*$AN$13,2))) | AO43: =IF($AN43="","",ROUND($AN43*$AO$13,2)) | AP43: =IF(ISERROR(IF($AM43="","",ROUND(SUM($X43,$AL43,$AO43),2))),"",IF($AM43="","",ROUND(SUM($X43,$AL43,$AO43),2))) | AQ43: =IF(ISERROR(IF($AM43="","",VLOOKUP(AP43,TRANSMUTATION_TABLE,4,TRUE))),"",IF($AM43="","",VLOOKUP(AP43,TRANSMUTATION_TABLE,4,TRUE)))
V44: =IF(COUNT($F44:$U44)=0,"",SUM($F44:$U44)) | W44: =IF(ISERROR(IF($V44="","",ROUND(($V44/$V$13)*$W$13,2))),"",IF($V44="","",ROUND(($V44/$V$13)*$W$13,2))) | X44: =IF($W44="","",ROUND($W44*$X$13,2)) | AJ44: =IF(COUNT($Y44:$AI44)=0,"",SUM($Y44:$AI44)) | AK44: =IF(ISERROR(IF($AJ44="","",ROUND(($AJ44/$AJ$13)*$AK$13,2))),"",IF($AJ44="","",ROUND(($AJ44/$AJ$13)*$AK$13,2))) | AL44: =IF($AK44="","",ROUND($AK44*$AL$13,2)) | AN44: =IF(ISERROR(IF($AM44="","",ROUND(($AM44/$AM$13)*$AN$13,2))),"",IF($AM44="","",ROUND(($AM44/$AM$13)*$AN$13,2))) | AO44: =IF($AN44="","",ROUND($AN44*$AO$13,2)) | AP44: =IF(ISERROR(IF($AM44="","",ROUND(SUM($X44,$AL44,$AO44),2))),"",IF($AM44="","",ROUND(SUM($X44,$AL44,$AO44),2))) | AQ44: =IF(ISERROR(IF($AM44="","",VLOOKUP(AP44,TRANSMUTATION_TABLE,4,TRUE))),"",IF($AM44="","",VLOOKUP(AP44,TRANSMUTATION_TABLE,4,TRUE)))
V45: =IF(COUNT($F45:$U45)=0,"",SUM($F45:$U45)) | W45: =IF(ISERROR(IF($V45="","",ROUND(($V45/$V$13)*$W$13,2))),"",IF($V45="","",ROUND(($V45/$V$13)*$W$13,2))) | X45: =IF($W45="","",ROUND($W45*$X$13,2)) | AJ45: =IF(COUNT($Y45:$AI45)=0,"",SUM($Y45:$AI45)) | AK45: =IF(ISERROR(IF($AJ45="","",ROUND(($AJ45/$AJ$13)*$AK$13,2))),"",IF($AJ45="","",ROUND(($AJ45/$AJ$13)*$AK$13,2))) | AL45: =IF($AK45="","",ROUND($AK45*$AL$13,2)) | AN45: =IF(ISERROR(IF($AM45="","",ROUND(($AM45/$AM$13)*$AN$13,2))),"",IF($AM45="","",ROUND(($AM45/$AM$13)*$AN$13,2))) | AO45: =IF($AN45="","",ROUND($AN45*$AO$13,2)) | AP45: =IF(ISERROR(IF($AM45="","",ROUND(SUM($X45,$AL45,$AO45),2))),"",IF($AM45="","",ROUND(SUM($X45,$AL45,$AO45),2))) | AQ45: =IF(ISERROR(IF($AM45="","",VLOOKUP(AP45,TRANSMUTATION_TABLE,4,TRUE))),"",IF($AM45="","",VLOOKUP(AP45,TRANSMUTATION_TABLE,4,TRUE)))
V49: =IF(COUNT($F49:$U49)=0,"",SUM($F49:$U49)) | W49: =IF(ISERROR(IF($V49="","",ROUND(($V49/$V$13)*$W$13,2))),"",IF($V49="","",ROUND(($V49/$V$13)*$W$13,2))) | X49: =IF($W49="","",ROUND($W49*$X$13,2)) | AJ49: =IF(COUNT($Y49:$AI49)=0,"",SUM($Y49:$AI49)) | AK49: =IF(ISERROR(IF($AJ49="","",ROUND(($AJ49/$AJ$13)*$AK$13,2))),"",IF($AJ49="","",ROUND(($AJ49/$AJ$13)*$AK$13,2))) | AL49: =IF($AK49="","",ROUND($AK49*$AL$13,2)) | AN49: =IF(ISERROR(IF($AM49="","",ROUND(($AM49/$AM$13)*$AN$13,2))),"",IF($AM49="","",ROUND(($AM49/$AM$13)*$AN$13,2))) | AO49: =IF($AN49="","",ROUND($AN49*$AO$13,2)) | AP49: =IF(ISERROR(IF($AM49="","",ROUND(SUM($X49,$AL49,$AO49),2))),"",IF($AM49="","",ROUND(SUM($X49,$AL49,$AO49),2))) | AQ49: =IF(ISERROR(IF($AM49="","",VLOOKUP(AP49,TRANSMUTATION_TABLE,4,TRUE))),"",IF($AM49="","",VLOOKUP(AP49,TRANSMUTATION_TABLE,4,TRUE)))
V50: =IF(COUNT($F50:$U50)=0,"",SUM($F50:$U50)) | W50: =IF(ISERROR(IF($V50="","",ROUND(($V50/$V$13)*$W$13,2))),"",IF($V50="","",ROUND(($V50/$V$13)*$W$13,2))) | X50: =IF($W50="","",ROUND($W50*$X$13,2)) | AJ50: =IF(COUNT($Y50:$AI50)=0,"",SUM($Y50:$AI50)) | AK50: =IF(ISERROR(IF($AJ50="","",ROUND(($AJ50/$AJ$13)*$AK$13,2))),"",IF($AJ50="","",ROUND(($AJ50/$AJ$13)*$AK$13,2))) | AL50: =IF($AK50="","",ROUND($AK50*$AL$13,2)) | AN50: =IF(ISERROR(IF($AM50="","",ROUND(($AM50/$AM$13)*$AN$13,2))),"",IF($AM50="","",ROUND(($AM50/$AM$13)*$AN$13,2))) | AO50: =IF($AN50="","",ROUND($AN50*$AO$13,2)) | AP50: =IF(ISERROR(IF($AM50="","",ROUND(SUM($X50,$AL50,$AO50),2))),"",IF($AM50="","",ROUND(SUM($X50,$AL50,$AO50),2))) | AQ50: =IF(ISERROR(IF($AM50="","",VLOOKUP(AP50,TRANSMUTATION_TABLE,4,TRUE))),"",IF($AM50="","",VLOOKUP(AP50,TRANSMUTATION_TABLE,4,TRUE)))
V51: =IF(COUNT($F51:$U51)=0,"",SUM($F51:$U51)) | W51: =IF(ISERROR(IF($V51="","",ROUND(($V51/$V$13)*$W$13,2))),"",IF($V51="","",ROUND(($V51/$V$13)*$W$13,2))) | X51: =IF($W51="","",ROUND($W51*$X$13,2)) | AJ51: =IF(COUNT($Y51:$AI51)=0,"",SUM($Y51:$AI51)) | AK51: =IF(ISERROR(IF($AJ51="","",ROUND(($AJ51/$AJ$13)*$AK$13,2))),"",IF($AJ51="","",ROUND(($AJ51/$AJ$13)*$AK$13,2))) | AL51: =IF($AK51="","",ROUND($AK51*$AL$13,2)) | AN51: =IF(ISERROR(IF($AM51="","",ROUND(($AM51/$AM$13)*$AN$13,2))),"",IF($AM51="","",ROUND(($AM51/$AM$13)*$AN$13,2))) | AO51: =IF($AN51="","",ROUND($AN51*$AO$13,2)) | AP51: =IF(ISERROR(IF($AM51="","",ROUND(SUM($X51,$AL51,$AO51),2))),"",IF($AM51="","",ROUND(SUM($X51,$AL51,$AO51),2))) | AQ51: =IF(ISERROR(IF($AM51="","",VLOOKUP(AP51,TRANSMUTATION_TABLE,4,TRUE))),"",IF($AM51="","",VLOOKUP(AP51,TRANSMUTATION_TABLE,4,TRUE)))
V52: =IF(COUNT($F52:$U52)=0,"",SUM($F52:$U52)) | W52: =IF(ISERROR(IF($V52="","",ROUND(($V52/$V$13)*$W$13,2))),"",IF($V52="","",ROUND(($V52/$V$13)*$W$13,2))) | X52: =IF($W52="","",ROUND($W52*$X$13,2)) | AJ52: =IF(COUNT($Y52:$AI52)=0,"",SUM($Y52:$AI52)) | AK52: =IF(ISERROR(IF($AJ52="","",ROUND(($AJ52/$AJ$13)*$AK$13,2))),"",IF($AJ52="","",ROUND(($AJ52/$AJ$13)*$AK$13,2))) | AL52: =IF($AK52="","",ROUND($AK52*$AL$13,2)) | AN52: =IF(ISERROR(IF($AM52="","",ROUND(($AM52/$AM$13)*$AN$13,2))),"",IF($AM52="","",ROUND(($AM52/$AM$13)*$AN$13,2))) | AO52: =IF($AN52="","",ROUND($AN52*$AO$13,2)) | AP52: =IF(ISERROR(IF($AM52="","",ROUND(SUM($X52,$AL52,$AO52),2))),"",IF($AM52="","",ROUND(SUM($X52,$AL52,$AO52),2))) | AQ52: =IF(ISERROR(IF($AM52="","",VLOOKUP(AP52,TRANSMUTATION_TABLE,4,TRUE))),"",IF($AM52="","",VLOOKUP(AP52,TRANSMUTATION_TABLE,4,TRUE)))
V53: =IF(COUNT($F53:$U53)=0,"",SUM($F53:$U53)) | W53: =IF(ISERROR(IF($V53="","",ROUND(($V53/$V$13)*$W$13,2))),"",IF($V53="","",ROUND(($V53/$V$13)*$W$13,2))) | X53: =IF($W53="","",ROUND($W53*$X$13,2)) | AJ53: =IF(COUNT($Y53:$AI53)=0,"",SUM($Y53:$AI53)) | AK53: =IF(ISERROR(IF($AJ53="","",ROUND(($AJ53/$AJ$13)*$AK$13,2))),"",IF($AJ53="","",ROUND(($AJ53/$AJ$13)*$AK$13,2))) | AL53: =IF($AK53="","",ROUND($AK53*$AL$13,2)) | AN53: =IF(ISERROR(IF($AM53="","",ROUND(($AM53/$AM$13)*$AN$13,2))),"",IF($AM53="","",ROUND(($AM53/$AM$13)*$AN$13,2))) | AO53: =IF($AN53="","",ROUND($AN53*$AO$13,2)) | AP53: =IF(ISERROR(IF($AM53="","",ROUND(SUM($X53,$AL53,$AO53),2))),"",IF($AM53="","",ROUND(SUM($X53,$AL53,$AO53),2))) | AQ53: =IF(ISERROR(IF($AM53="","",VLOOKUP(AP53,TRANSMUTATION_TABLE,4,TRUE))),"",IF($AM53="","",VLOOKUP(AP53,TRANSMUTATION_TABLE,4,TRUE)))
...

Sheet SCIENCE_Q2
A1: Class Record
A3: (Pursuant to Deped Order 8 series of 2015)
C4: REGION | G4: NCR | U4: DIVISION | V4: PARAÑAQUE | Z4: DISTRICT | AH4: VII
B6: SCHOOL NAME | G6: PARAÑAQUE NATIONAL HIGH SCHOOL - BACLARAN | Z6: SCHOOL ID | AH6: 305426 | AK6: SCHOOL YEAR | AN6: 2025 - 2026
A8: SECOND QUARTER | F8: GRADE & SECTION: | O8: IX - | W8: TEACHER: | Y8: MRS. VANESSA G. LAS PIÑAS - TALENTO | AJ8: SUBJECT: | AL8: SCIENCE 9
B9: LEARNERS' NAMES | F9: WRITTEN WORKS (40%) | Y9: PERFORMANCE TASKS (40%) | AM9: QUARTERLY ASSESSMENT (20%) | AP9: Initial Grade | AQ9: Quarterly Grade
F10: SEATWORK / QUIZZES / ASSIGNMENTS | U10: Notebook | Y10: GROUP ACTIVITY | AI10: Recitation
F11: (Let's Recall, Let's Apply, Let's Analyze, Let's Try) | Y11: Let's Create | AM11: Periodic Test
F12: 1 | G12: 2 | H12: 3 | I12: 4 | J12: 5 | K12: 6 | L12: 7 | M12: 8 | N12: 9 | O12: 10 | P12: 11 | Q12: 12 | R12: 13 | S12: 14 | T12: 15 | U12: 2 | V12: Total | W12: PS | X12: WS | Y12: 1 | Z12: 2 | AA12: 3 | AB12: 4 | AC12: 5 | AD12: 6 | AE12: 7 | AF12: 8 | AG12: 9 | AH12: 10 | AI12: 2 | AJ12: Total | AK12: PS | AL12: WS | AM12: 2 | AN12: PS | AO12: WS
B13: HIGHEST POSSIBLE SCORE | V13: =IF(COUNT($F13:$U13)=0,"",SUM($F13:$U13)) | W13: 100 | X13: 0.4 | AJ13: =IF(COUNT($Y13:$AI13)=0,"",SUM($Y13:$AI13)) | AK13: 100 | AL13: 0.4 | AM13: 40 | AN13: 100 | AO13: 0.2
B14: MALE
A15: 1 | V15: =IF(COUNT($F15:$U15)=0,"",SUM($F15:$U15)) | W15: =IF(ISERROR(IF($V15="","",ROUND(($V15/$V$13)*$W$13,2))),"",IF($V15="","",ROUND(($V15/$V$13)*$W$13,2))) | X15: =IF($W15="","",ROUND($W15*$X$13,2)) | AJ15: =IF(COUNT($Y15:$AI15)=0,"",SUM($Y15:$AI15)) | AK15: =IF(ISERROR(IF($AJ15="","",ROUND(($AJ15/$AJ$13)*$AK$13,2))),"",IF($AJ15="","",ROUND(($AJ15/$AJ$13)*$AK$13,2))) | AL15: =IF($AK15="","",ROUND($AK15*$AL$13,2)) | AN15: =IF(ISERROR(IF($AM15="","",ROUND(($AM15/$AM$13)*$AN$13,2))),"",IF($AM15="","",ROUND(($AM15/$AM$13)*$AN$13,2))) | AO15: =IF($AN15="","",ROUND($AN15*$AO$13,2)) | AP15: =IF(ISERROR(IF($AM15="","",ROUND(SUM($X15,$AL15,$AO15),2))),"",IF($AM15="","",ROUND(SUM($X15,$AL15,$AO15),2))) | AQ15: =IF(ISERROR(IF($AM15="","",VLOOKUP(AP15,TRANSMUTATION_TABLE,4,TRUE))),"",IF($AM15="","",VLOOKUP(AP15,TRANSMUTATION_TABLE,4,TRUE))) | AT15: 60-69 | AU15: 78
A16: 2 | V16: =IF(COUNT($F16:$U16)=0,"",SUM($F16:$U16)) | W16: =IF(ISERROR(IF($V16="","",ROUND(($V16/$V$13)*$W$13,2))),"",IF($V16="","",ROUND(($V16/$V$13)*$W$13,2))) | X16: =IF($W16="","",ROUND($W16*$X$13,2)) | AJ16: =IF(COUNT($Y16:$AI16)=0,"",SUM($Y16:$AI16)) | AK16: =IF(ISERROR(IF($AJ16="","",ROUND(($AJ16/$AJ$13)*$AK$13,2))),"",IF($AJ16="","",ROUND(($AJ16/$AJ$13)*$AK$13,2))) | AL16: =IF($AK16="","",ROUND($AK16*$AL$13,2)) | AN16: =IF(ISERROR(IF($AM16="","",ROUND(($AM16/$AM$13)*$AN$13,2))),"",IF($AM16="","",ROUND(($AM16/$AM$13)*$AN$13,2))) | AO16: =IF($AN16="","",ROUND($AN16*$AO$13,2)) | AP16: =IF(ISERROR(IF($AM16="","",ROUND(SUM($X16,$AL16,$AO16),2))),"",IF($AM16="","",ROUND(SUM($X16,$AL16,$AO16),2))) | AQ16: =IF(ISERROR(IF($AM16="","",VLOOKUP(AP16,TRANSMUTATION_TABLE,4,TRUE))),"",IF($AM16="","",VLOOKUP(AP16,TRANSMUTATION_TABLE,4,TRUE))) | AT16: 70-74 | AU16: 79
A17: 3 | V17: =IF(COUNT($F17:$U17)=0,"",SUM($F17:$U17)) | W17: =IF(ISERROR(IF($V17="","",ROUND(($V17/$V$13)*$W$13,2))),"",IF($V17="","",ROUND(($V17/$V$13)*$W$13,2))) | X17: =IF($W17="","",ROUND($W17*$X$13,2)) | AJ17: =IF(COUNT($Y17:$AI17)=0,"",SUM($Y17:$AI17)) | AK17: =IF(ISERROR(IF($AJ17="","",ROUND(($AJ17/$AJ$13)*$AK$13,2))),"",IF($AJ17="","",ROUND(($AJ17/$AJ$13)*$AK$13,2))) | AL17: =IF($AK17="","",ROUND($AK17*$AL$13,2)) | AN17: =IF(ISERROR(IF($AM17="","",ROUND(($AM17/$AM$13)*$AN$13,2))),"",IF($AM17="","",ROUND(($AM17/$AM$13)*$AN$13,2))) | AO17: =IF($AN17="","",ROUND($AN17*$AO$13,2)) | AP17: =IF(ISERROR(IF($AM17="","",ROUND(SUM($X17,$AL17,$AO17),2))),"",IF($AM17="","",ROUND(SUM($X17,$AL17,$AO17),2))) | AQ17: =IF(ISERROR(IF($AM17="","",VLOOKUP(AP17,TRANSMUTATION_TABLE,4,TRUE))),"",IF($AM17="","",VLOOKUP(AP17,TRANSMUTATION_TABLE,4,TRUE))) | AT17: 75-79 | AU17: 80
A18: 4 | V18: =IF(COUNT($F18:$U18)=0,"",SUM($F18:$U18)) | W18: =IF(ISERROR(IF($V18="","",ROUND(($V18/$V$13)*$W$13,2))),"",IF($V18="","",ROUND(($V18/$V$13)*$W$13,2))) | X18: =IF($W18="","",ROUND($W18*$X$13,2)) | AJ18: =IF(COUNT($Y18:$AI18)=0,"",SUM($Y18:$AI18)) | AK18: =IF(ISERROR(IF($AJ18="","",ROUND(($AJ18/$AJ$13)*$AK$13,2))),"",IF($AJ18="","",ROUND(($AJ18/$AJ$13)*$AK$13,2))) | AL18: =IF($AK18="","",ROUND($AK18*$AL$13,2)) | AN18: =IF(ISERROR(IF($AM18="","",ROUND(($AM18/$AM$13)*$AN$13,2))),"",IF($AM18="","",ROUND(($AM18/$AM$13)*$AN$13,2))) | AO18: =IF($AN18="","",ROUND($AN18*$AO$13,2)) | AP18: =IF(ISERROR(IF($AM18="","",ROUND(SUM($X18,$AL18,$AO18),2))),"",IF($AM18="","",ROUND(SUM($X18,$AL18,$AO18),2))) | AQ18: =IF(ISERROR(IF($AM18="","",VLOOKUP(AP18,TRANSMUTATION_TABLE,4,TRUE))),"",IF($AM18="","",VLOOKUP(AP18,TRANSMUTATION_TABLE,4,TRUE))) | AT18: 80-84 | AU18: 85
A19: 5 | V19: =IF(COUNT($F19:$U19)=0,"",SUM($F19:$U19)) | W19: =IF(ISERROR(IF($V19="","",ROUND(($V19/$V$13)*$W$13,2))),"",IF($V19="","",ROUND(($V19/$V$13)*$W$13,2))) | X19: =IF($W19="","",ROUND($W19*$X$13,2)) | AJ19: =IF(COUNT($Y19:$AI19)=0,"",SUM($Y19:$AI19)) | AK19: =IF(ISERROR(IF($AJ19="","",ROUND(($AJ19/$AJ$13)*$AK$13,2))),"",IF($AJ19="","",ROUND(($AJ19/$AJ$13)*$AK$13,2))) | AL19: =IF($AK19="","",ROUND($AK19*$AL$13,2)) | AN19: =IF(ISERROR(IF($AM19="","",ROUND(($AM19/$AM$13)*$AN$13,2))),"",IF($AM19="","",ROUND(($AM19/$AM$13)*$AN$13,2))) | AO19: =IF($AN19="","",ROUND($AN19*$AO$13,2)) | AP19: =IF(ISERROR(IF($AM19="","",ROUND(SUM($X19,$AL19,$AO19),2))),"",IF($AM19="","",ROUND(SUM($X19,$AL19,$AO19),2))) | AQ19: =IF(ISERROR(IF($AM19="","",VLOOKUP(AP19,TRANSMUTATION_TABLE,4,TRUE))),"",IF($AM19="","",VLOOKUP(AP19,TRANSMUTATION_TABLE,4,TRUE))) | AT19: 85-88 | AU19: 89
A20: 15 | V20: =IF(COUNT($F20:$U20)=0,"",SUM($F20:$U20)) | W20: =IF(ISERROR(IF($V20="","",ROUND(($V20/$V$13)*$W$13,2))),"",IF($V20="","",ROUND(($V20/$V$13)*$W$13,2))) | X20: =IF($W20="","",ROUND($W20*$X$13,2)) | AJ20: =IF(COUNT($Y20:$AI20)=0,"",SUM($Y20:$AI20)) | AK20: =IF(ISERROR(IF($AJ20="","",ROUND(($AJ20/$AJ$13)*$AK$13,2))),"",IF($AJ20="","",ROUND(($AJ20/$AJ$13)*$AK$13,2))) | AL20: =IF($AK20="","",ROUND($AK20*$AL$13,2)) | AN20: =IF(ISERROR(IF($AM20="","",ROUND(($AM20/$AM$13)*$AN$13,2))),"",IF($AM20="","",ROUND(($AM20/$AM$13)*$AN$13,2))) | AO20: =IF($AN20="","",ROUND($AN20*$AO$13,2)) | AP20: =IF(ISERROR(IF($AM20="","",ROUND(SUM($X20,$AL20,$AO20),2))),"",IF($AM20="","",ROUND(SUM($X20,$AL20,$AO20),2))) | AQ20: =IF(ISERROR(IF($AM20="","",VLOOKUP(AP20,TRANSMUTATION_TABLE,4,TRUE))),"",IF($AM20="","",VLOOKUP(AP20,TRANSMUTATION_TABLE,4,TRUE))) | AT20: 89-91 | AU20: 92
A21: 7 | V21: =IF(COUNT($F21:$U21)=0,"",SUM($F21:$U21)) | W21: =IF(ISERROR(IF($V21="","",ROUND(($V21/$V$13)*$W$13,2))),"",IF($V21="","",ROUND(($V21/$V$13)*$W$13,2))) | X21: =IF($W21="","",ROUND($W21*$X$13,2)) | AJ21: =IF(COUNT($Y21:$AI21)=0,"",SUM($Y21:$AI21)) | AK21: =IF(ISERROR(IF($AJ21="","",ROUND(($AJ21/$AJ$13)*$AK$13,2))),"",IF($AJ21="","",ROUND(($AJ21/$AJ$13)*$AK$13,2))) | AL21: =IF($AK21="","",ROUND($AK21*$AL$13,2)) | AN21: =IF(ISERROR(IF($AM21="","",ROUND(($AM21/$AM$13)*$AN$13,2))),"",IF($AM21="","",ROUND(($AM21/$AM$13)*$AN$13,2))) | AO21: =IF($AN21="","",ROUND($AN21*$AO$13,2)) | AP21: =IF(ISERROR(IF($AM21="","",ROUND(SUM($X21,$AL21,$AO21),2))),"",IF($AM21="","",ROUND(SUM($X21,$AL21,$AO21),2))) | AQ21: =IF(ISERROR(IF($AM21="","",VLOOKUP(AP21,TRANSMUTATION_TABLE,4,TRUE))),"",IF($AM21="","",VLOOKUP(AP21,TRANSMUTATION_TABLE,4,TRUE)))
A22: 8 | V22: =IF(COUNT($F22:$U22)=0,"",SUM($F22:$U22)) | W22: =IF(ISERROR(IF($V22="","",ROUND(($V22/$V$13)*$W$13,2))),"",IF($V22="","",ROUND(($V22/$V$13)*$W$13,2))) | X22: =IF($W22="","",ROUND($W22*$X$13,2)) | AJ22: =IF(COUNT($Y22:$AI22)=0,"",SUM($Y22:$AI22)) | AK22: =IF(ISERROR(IF($AJ22="","",ROUND(($AJ22/$AJ$13)*$AK$13,2))),"",IF($AJ22="","",ROUND(($AJ22/$AJ$13)*$AK$13,2))) | AL22: =IF($AK22="","",ROUND($AK22*$AL$13,2)) | AN22: =IF(ISERROR(IF($AM22="","",ROUND(($AM22/$AM$13)*$AN$13,2))),"",IF($AM22="","",ROUND(($AM22/$AM$13)*$AN$13,2))) | AO22: =IF($AN22="","",ROUND($AN22*$AO$13,2)) | AP22: =IF(ISERROR(IF($AM22="","",ROUND(SUM($X22,$AL22,$AO22),2))),"",IF($AM22="","",ROUND(SUM($X22,$AL22,$AO22),2))) | AQ22: =IF(ISERROR(IF($AM22="","",VLOOKUP(AP22,TRANSMUTATION_TABLE,4,TRUE))),"",IF($AM22="","",VLOOKUP(AP22,TRANSMUTATION_TABLE,4,TRUE)))
A23: 9 | V23: =IF(COUNT($F23:$U23)=0,"",SUM($F23:$U23)) | W23: =IF(ISERROR(IF($V23="","",ROUND(($V23/$V$13)*$W$13,2))),"",IF($V23="","",ROUND(($V23/$V$13)*$W$13,2))) | X23: =IF($W23="","",ROUND($W23*$X$13,2)) | AJ23: =IF(COUNT($Y23:$AI23)=0,"",SUM($Y23:$AI23)) | AK23: =IF(ISERROR(IF($AJ23="","",ROUND(($AJ23/$AJ$13)*$AK$13,2))),"",IF($AJ23="","",ROUND(($AJ23/$AJ$13)*$AK$13,2))) | AL23: =IF($AK23="","",ROUND($AK23*$AL$13,2)) | AN23: =IF(ISERROR(IF($AM23="","",ROUND(($AM23/$AM$13)*$AN$13,2))),"",IF($AM23="","",ROUND(($AM23/$AM$13)*$AN$13,2))) | AO23: =IF($AN23="","",ROUND($AN23*$AO$13,2)) | AP23: =IF(ISERROR(IF($AM23="","",ROUND(SUM($X23,$AL23,$AO23),2))),"",IF($AM23="","",ROUND(SUM($X23,$AL23,$AO23),2))) | AQ23: =IF(ISERROR(IF($AM23="","",VLOOKUP(AP23,TRANSMUTATION_TABLE,4,TRUE))),"",IF($AM23="","",VLOOKUP(AP23,TRANSMUTATION_TABLE,4,TRUE)))
A24: 10 | V24: =IF(COUNT($F24:$U24)=0,"",SUM($F24:$U24)) | W24: =IF(ISERROR(IF($V24="","",ROUND(($V24/$V$13)*$W$13,2))),"",IF($V24="","",ROUND(($V24/$V$13)*$W$13,2))) | X24: =IF($W24="","",ROUND($W24*$X$13,2)) | AJ24: =IF(COUNT($Y24:$AI24)=0,"",SUM($Y24:$AI24)) | AK24: =IF(ISERROR(IF($AJ24="","",ROUND(($AJ24/$AJ$13)*$AK$13,2))),"",IF($AJ24="","",ROUND(($AJ24/$AJ$13)*$AK$13,2))) | AL24: =IF($AK24="","",ROUND($AK24*$AL$13,2)) | AN24: =IF(ISERROR(IF($AM24="","",ROUND(($AM24/$AM$13)*$AN$13,2))),"",IF($AM24="","",ROUND(($AM24/$AM$13)*$AN$13,2))) | AO24: =IF($AN24="","",ROUND($AN24*$AO$13,2)) | AP24: =IF(ISERROR(IF($AM24="","",ROUND(SUM($X24,$AL24,$AO24),2))),"",IF($AM24="","",ROUND(SUM($X24,$AL24,$AO24),2))) | AQ24: =IF(ISERROR(IF($AM24="","",VLOOKUP(AP24,TRANSMUTATION_TABLE,4,TRUE))),"",IF($AM24="","",VLOOKUP(AP24,TRANSMUTATION_TABLE,4,TRUE)))
A25: 11 | V25: =IF(COUNT($F25:$U25)=0,"",SUM($F25:$U25)) | W25: =IF(ISERROR(IF($V25="","",ROUND(($V25/$V$13)*$W$13,2))),"",IF($V25="","",ROUND(($V25/$V$13)*$W$13,2))) | X25: =IF($W25="","",ROUND($W25*$X$13,2)) | AJ25: =IF(COUNT($Y25:$AI25)=0,"",SUM($Y25:$AI25)) | AK25: =IF(ISERROR(IF($AJ25="","",ROUND(($AJ25/$AJ$13)*$AK$13,2))),"",IF($AJ25="","",ROUND(($AJ25/$AJ$13)*$AK$13,2))) | AL25: =IF($AK25="","",ROUND($AK25*$AL$13,2)) | AN25: =IF(ISERROR(IF($AM25="","",ROUND(($AM25/$AM$13)*$AN$13,2))),"",IF($AM25="","",ROUND(($AM25/$AM$13)*$AN$13,2))) | AO25: =IF($AN25="","",ROUND($AN25*$AO$13,2)) | AP25: =IF(ISERROR(IF($AM25="","",ROUND(SUM($X25,$AL25,$AO25),2))),"",IF($AM25="","",ROUND(SUM($X25,$AL25,$AO25),2))) | AQ25: =IF(ISERROR(IF($AM25="","",VLOOKUP(AP25,TRANSMUTATION_TABLE,4,TRUE))),"",IF($AM25="","",VLOOKUP(AP25,TRANSMUTATION_TABLE,4,TRUE)))
A26: 12 | V26: =IF(COUNT($F26:$U26)=0,"",SUM($F26:$U26)) | W26: =IF(ISERROR(IF($V26="","",ROUND(($V26/$V$13)*$W$13,2))),"",IF($V26="","",ROUND(($V26/$V$13)*$W$13,2))) | X26: =IF($W26="","",ROUND($W26*$X$13,2)) | AJ26: =IF(COUNT($Y26:$AI26)=0,"",SUM($Y26:$AI26)) | AK26: =IF(ISERROR(IF($AJ26="","",ROUND(($AJ26/$AJ$13)*$AK$13,2))),"",IF($AJ26="","",ROUND(($AJ26/$AJ$13)*$AK$13,2))) | AL26: =IF($AK26="","",ROUND($AK26*$AL$13,2)) | AN26: =IF(ISERROR(IF($AM26="","",ROUND(($AM26/$AM$13)*$AN$13,2))),"",IF($AM26="","",ROUND(($AM26/$AM$13)*$AN$13,2))) | AO26: =IF($AN26="","",ROUND($AN26*$AO$13,2)) | AP26: =IF(ISERROR(IF($AM26="","",ROUND(SUM($X26,$AL26,$AO26),2))),"",IF($AM26="","",ROUND(SUM($X26,$AL26,$AO26),2))) | AQ26: =IF(ISERROR(IF($AM26="","",VLOOKUP(AP26,TRANSMUTATION_TABLE,4,TRUE))),"",IF($AM26="","",VLOOKUP(AP26,TRANSMUTATION_TABLE,4,TRUE)))
A27: 13 | V27: =IF(COUNT($F27:$U27)=0,"",SUM($F27:$U27)) | W27: =IF(ISERROR(IF($V27="","",ROUND(($V27/$V$13)*$W$13,2))),"",IF($V27="","",ROUND(($V27/$V$13)*$W$13,2))) | X27: =IF($W27="","",ROUND($W27*$X$13,2)) | AJ27: =IF(COUNT($Y27:$AI27)=0,"",SUM($Y27:$AI27)) | AK27: =IF(ISERROR(IF($AJ27="","",ROUND(($AJ27/$AJ$13)*$AK$13,2))),"",IF($AJ27="","",ROUND(($AJ27/$AJ$13)*$AK$13,2))) | AL27: =IF($AK27="","",ROUND($AK27*$AL$13,2)) | AN27: =IF(ISERROR(IF($AM27="","",ROUND(($AM27/$AM$13)*$AN$13,2))),"",IF($AM27="","",ROUND(($AM27/$AM$13)*$AN$13,2))) | AO27: =IF($AN27="","",ROUND($AN27*$AO$13,2)) | AP27: =IF(ISERROR(IF($AM27="","",ROUND(SUM($X27,$AL27,$AO27),2))),"",IF($AM27="","",ROUND(SUM($X27,$AL27,$AO27),2))) | AQ27: =IF(ISERROR(IF($AM27="","",VLOOKUP(AP27,TRANSMUTATION_TABLE,4,TRUE))),"",IF($AM27="","",VLOOKUP(AP27,TRANSMUTATION_TABLE,4,TRUE)))
A28: 14 | V28: =IF(COUNT($F28:$U28)=0,"",SUM($F28:$U28)) | W28: =IF(ISERROR(IF($V28="","",ROUND(($V28/$V$13)*$W$13,2))),"",IF($V28="","",ROUND(($V28/$V$13)*$W$13,2))) | X28: =IF($W28="","",ROUND($W28*$X$13,2)) | AJ28: =IF(COUNT($Y28:$AI28)=0,"",SUM($Y28:$AI28)) | AK28: =IF(ISERROR(IF($AJ28="","",ROUND(($AJ28/$AJ$13)*$AK$13,2))),"",IF($AJ28="","",ROUND(($AJ28/$AJ$13)*$AK$13,2))) | AL28: =IF($AK28="","",ROUND($AK28*$AL$13,2)) | AN28: =IF(ISERROR(IF($AM28="","",ROUND(($AM28/$AM$13)*$AN$13,2))),"",IF($AM28="","",ROUND(($AM28/$AM$13)*$AN$13,2))) | AO28: =IF($AN28="","",ROUND($AN28*$AO$13,2)) | AP28: =IF(ISERROR(IF($AM28="","",ROUND(SUM($X28,$AL28,$AO28),2))),"",IF($AM28="","",ROUND(SUM($X28,$AL28,$AO28),2))) | AQ28: =IF(ISERROR(IF($AM28="","",VLOOKUP(AP28,TRANSMUTATION_TABLE,4,TRUE))),"",IF($AM28="","",VLOOKUP(AP28,TRANSMUTATION_TABLE,4,TRUE)))
A29: 15 | V29: =IF(COUNT($F29:$U29)=0,"",SUM($F29:$U29)) | W29: =IF(ISERROR(IF($V29="","",ROUND(($V29/$V$13)*$W$13,2))),"",IF($V29="","",ROUND(($V29/$V$13)*$W$13,2))) | X29: =IF($W29="","",ROUND($W29*$X$13,2)) | AJ29: =IF(COUNT($Y29:$AI29)=0,"",SUM($Y29:$AI29)) | AK29: =IF(ISERROR(IF($AJ29="","",ROUND(($AJ29/$AJ$13)*$AK$13,2))),"",IF($AJ29="","",ROUND(($AJ29/$AJ$13)*$AK$13,2))) | AL29: =IF($AK29="","",ROUND($AK29*$AL$13,2)) | AN29: =IF(ISERROR(IF($AM29="","",ROUND(($AM29/$AM$13)*$AN$13,2))),"",IF($AM29="","",ROUND(($AM29/$AM$13)*$AN$13,2))) | AO29: =IF($AN29="","",ROUND($AN29*$AO$13,2)) | AP29: =IF(ISERROR(IF($AM29="","",ROUND(SUM($X29,$AL29,$AO29),2))),"",IF($AM29="","",ROUND(SUM($X29,$AL29,$AO29),2))) | AQ29: =IF(ISERROR(IF($AM29="","",VLOOKUP(AP29,TRANSMUTATION_TABLE,4,TRUE))),"",IF($AM29="","",VLOOKUP(AP29,TRANSMUTATION_TABLE,4,TRUE)))
A30: 16 | V30: =IF(COUNT($F30:$U30)=0,"",SUM($F30:$U30)) | W30: =IF(ISERROR(IF($V30="","",ROUND(($V30/$V$13)*$W$13,2))),"",IF($V30="","",ROUND(($V30/$V$13)*$W$13,2))) | X30: =IF($W30="","",ROUND($W30*$X$13,2)) | AJ30: =IF(COUNT($Y30:$AI30)=0,"",SUM($Y30:$AI30)) | AK30: =IF(ISERROR(IF($AJ30="","",ROUND(($AJ30/$AJ$13)*$AK$13,2))),"",IF($AJ30="","",ROUND(($AJ30/$AJ$13)*$AK$13,2))) | AL30: =IF($AK30="","",ROUND($AK30*$AL$13,2)) | AN30: =IF(ISERROR(IF($AM30="","",ROUND(($AM30/$AM$13)*$AN$13,2))),"",IF($AM30="","",ROUND(($AM30/$AM$13)*$AN$13,2))) | AO30: =IF($AN30="","",ROUND($AN30*$AO$13,2)) | AP30: =IF(ISERROR(IF($AM30="","",ROUND(SUM($X30,$AL30,$AO30),2))),"",IF($AM30="","",ROUND(SUM($X30,$AL30,$AO30),2))) | AQ30: =IF(ISERROR(IF($AM30="","",VLOOKUP(AP30,TRANSMUTATION_TABLE,4,TRUE))),"",IF($AM30="","",VLOOKUP(AP30,TRANSMUTATION_TABLE,4,TRUE)))
A31: 17 | V31: =IF(COUNT($F31:$U31)=0,"",SUM($F31:$U31)) | W31: =IF(ISERROR(IF($V31="","",ROUND(($V31/$V$13)*$W$13,2))),"",IF($V31="","",ROUND(($V31/$V$13)*$W$13,2))) | X31: =IF($W31="","",ROUND($W31*$X$13,2)) | AJ31: =IF(COUNT($Y31:$AI31)=0,"",SUM($Y31:$AI31)) | AK31: =IF(ISERROR(IF($AJ31="","",ROUND(($AJ31/$AJ$13)*$AK$13,2))),"",IF($AJ31="","",ROUND(($AJ31/$AJ$13)*$AK$13,2))) | AL31: =IF($AK31="","",ROUND($AK31*$AL$13,2)) | AN31: =IF(ISERROR(IF($AM31="","",ROUND(($AM31/$AM$13)*$AN$13,2))),"",IF($AM31="","",ROUND(($AM31/$AM$13)*$AN$13,2))) | AO31: =IF($AN31="","",ROUND($AN31*$AO$13,2)) | AP31: =IF(ISERROR(IF($AM31="","",ROUND(SUM($X31,$AL31,$AO31),2))),"",IF($AM31="","",ROUND(SUM($X31,$AL31,$AO31),2))) | AQ31: =IF(ISERROR(IF($AM31="","",VLOOKUP(AP31,TRANSMUTATION_TABLE,4,TRUE))),"",IF($AM31="","",VLOOKUP(AP31,TRANSMUTATION_TABLE,4,TRUE)))
A32: 18 | V32: =IF(COUNT($F32:$U32)=0,"",SUM($F32:$U32)) | W32: =IF(ISERROR(IF($V32="","",ROUND(($V32/$V$13)*$W$13,2))),"",IF($V32="","",ROUND(($V32/$V$13)*$W$13,2))) | X32: =IF($W32="","",ROUND($W32*$X$13,2)) | AJ32: =IF(COUNT($Y32:$AI32)=0,"",SUM($Y32:$AI32)) | AK32: =IF(ISERROR(IF($AJ32="","",ROUND(($AJ32/$AJ$13)*$AK$13,2))),"",IF($AJ32="","",ROUND(($AJ32/$AJ$13)*$AK$13,2))) | AL32: =IF($AK32="","",ROUND($AK32*$AL$13,2)) | AN32: =IF(ISERROR(IF($AM32="","",ROUND(($AM32/$AM$13)*$AN$13,2))),"",IF($AM32="","",ROUND(($AM32/$AM$13)*$AN$13,2))) | AO32: =IF($AN32="","",ROUND($AN32*$AO$13,2)) | AP32: =IF(ISERROR(IF($AM32="","",ROUND(SUM($X32,$AL32,$AO32),2))),"",IF($AM32="","",ROUND(SUM($X32,$AL32,$AO32),2))) | AQ32: =IF(ISERROR(IF($AM32="","",VLOOKUP(AP32,TRANSMUTATION_TABLE,4,TRUE))),"",IF($AM32="","",VLOOKUP(AP32,TRANSMUTATION_TABLE,4,TRUE)))
... A34: 20 | V34: =IF(COUNT($F34:$U34)=0,"",SUM($F34:$U34)) | W34: =IF(ISERROR(IF($V34="","",ROUND(($V34/$V$13)*$W$13,2))),"",IF($V34="","",ROUND(($V34/$V$13)*$W$13,2))) | X34: =IF($W34="","",ROUND($W34*$X$13,2)) | AJ34: =IF(COUNT($Y34:$AI34)=0,"",SUM($Y34:$AI34)) | AK34: =IF(ISERROR(IF($AJ34="","",ROUND(($AJ34/$AJ$13)*$AK$13,2))),"",IF($AJ34="","",ROUND(($AJ34/$AJ$13)*$AK$13,2))) | AL34: =IF($AK34="","",ROUND($AK34*$AL$13,2)) | AN34: =IF(ISERROR(IF($AM34="","",ROUND(($AM34/$AM$13)*$AN$13,2))),"",IF($AM34="","",ROUND(($AM34/$AM$13)*$AN$13,2))) | AO34: =IF($AN34="","",ROUND($AN34*$AO$13,2)) | AP34: =IF(ISERROR(IF($AM34="","",ROUND(SUM($X34,$AL34,$AO34),2))),"",IF($AM34="","",ROUND(SUM($X34,$AL34,$AO34),2))) | AQ34: =IF(ISERROR(IF($AM34="","",VLOOKUP(AP34,TRANSMUTATION_TABLE,4,TRUE))),"",IF($AM34="","",VLOOKUP(AP34,TRANSMUTATION_TABLE,4,TRUE)))
A35: 21 | V35: =IF(COUNT($F35:$U35)=0,"",SUM($F35:$U35)) | W35: =IF(ISERROR(IF($V35="","",ROUND(($V35/$V$13)*$W$13,2))),"",IF($V35="","",ROUND(($V35/$V$13)*$W$13,2))) | X35: =IF($W35="","",ROUND($W35*$X$13,2)) | AK35: =IF(ISERROR(IF($AJ35="","",ROUND(($AJ35/$AJ$13)*$AK$13,2))),"",IF($AJ35="","",ROUND(($AJ35/$AJ$13)*$AK$13,2))) | AL35: =IF($AK35="","",ROUND($AK35*$AL$13,2)) | AN35: =IF(ISERROR(IF($AM35="","",ROUND(($AM35/$AM$13)*$AN$13,2))),"",IF($AM35="","",ROUND(($AM35/$AM$13)*$AN$13,2))) | AO35: =IF($AN35="","",ROUND($AN35*$AO$13,2)) | AP35: =IF(ISERROR(IF($AM35="","",ROUND(SUM($X35,$AL35,$AO35),2))),"",IF($AM35="","",ROUND(SUM($X35,$AL35,$AO35),2))) | AQ35: =IF(ISERROR(IF($AM35="","",VLOOKUP(AP35,TRANSMUTATION_TABLE,4,TRUE))),"",IF($AM35="","",VLOOKUP(AP35,TRANSMUTATION_TABLE,4,TRUE)))
A36: 22 | V36: =IF(COUNT($F36:$U36)=0,"",SUM($F36:$U36)) | W36: =IF(ISERROR(IF($V36="","",ROUND(($V36/$V$13)*$W$13,2))),"",IF($V36="","",ROUND(($V36/$V$13)*$W$13,2))) | X36: =IF($W36="","",ROUND($W36*$X$13,2)) | AJ36: =IF(COUNT($Y36:$AI36)=0,"",SUM($Y36:$AI36)) | AK36: =IF(ISERROR(IF($AJ36="","",ROUND(($AJ36/$AJ$13)*$AK$13,2))),"",IF($AJ36="","",ROUND(($AJ36/$AJ$13)*$AK$13,2))) | AL36: =IF($AK36="","",ROUND($AK36*$AL$13,2)) | AN36: =IF(ISERROR(IF($AM36="","",ROUND(($AM36/$AM$13)*$AN$13,2))),"",IF($AM36="","",ROUND(($AM36/$AM$13)*$AN$13,2))) | AO36: =IF($AN36="","",ROUND($AN36*$AO$13,2)) | AP36: =IF(ISERROR(IF($AM36="","",ROUND(SUM($X36,$AL36,$AO36),2))),"",IF($AM36="","",ROUND(SUM($X36,$AL36,$AO36),2))) | AQ36: =IF(ISERROR(IF($AM36="","",VLOOKUP(AP36,TRANSMUTATION_TABLE,4,TRUE))),"",IF($AM36="","",VLOOKUP(AP36,TRANSMUTATION_TABLE,4,TRUE)))
AQ37: =IF(ISERROR(IF($AM37="","",VLOOKUP(AP37,TRANSMUTATION_TABLE,4,TRUE))),"",IF($AM37="","",VLOOKUP(AP37,TRANSMUTATION_TABLE,4,TRUE)))
V38: =IF(COUNT($F38:$U38)=0,"",SUM($F38:$U38)) | W38: =IF(ISERROR(IF($V38="","",ROUND(($V38/$V$13)*$W$13,2))),"",IF($V38="","",ROUND(($V38/$V$13)*$W$13,2))) | X38: =IF($W38="","",ROUND($W38*$X$13,2)) | AJ38: =IF(COUNT($Y38:$AI38)=0,"",SUM($Y38:$AI38)) | AK38: =IF(ISERROR(IF($AJ38="","",ROUND(($AJ38/$AJ$13)*$AK$13,2))),"",IF($AJ38="","",ROUND(($AJ38/$AJ$13)*$AK$13,2))) | AL38: =IF($AK38="","",ROUND($AK38*$AL$13,2)) | AN38: =IF(ISERROR(IF($AM38="","",ROUND(($AM38/$AM$13)*$AN$13,2))),"",IF($AM38="","",ROUND(($AM38/$AM$13)*$AN$13,2))) | AO38: =IF($AN38="","",ROUND($AN38*$AO$13,2)) | AP38: =IF(ISERROR(IF($AM38="","",ROUND(SUM($X38,$AL38,$AO38),2))),"",IF($AM38="","",ROUND(SUM($X38,$AL38,$AO38),2))) | AQ38: =IF(ISERROR(IF($AM38="","",VLOOKUP(AP38,TRANSMUTATION_TABLE,4,TRUE))),"",IF($AM38="","",VLOOKUP(AP38,TRANSMUTATION_TABLE,4,TRUE)))
V39: =IF(COUNT($F39:$U39)=0,"",SUM($F39:$U39)) | W39: =IF(ISERROR(IF($V39="","",ROUND(($V39/$V$13)*$W$13,2))),"",IF($V39="","",ROUND(($V39/$V$13)*$W$13,2))) | X39: =IF($W39="","",ROUND($W39*$X$13,2)) | AJ39: =IF(COUNT($Y39:$AI39)=0,"",SUM($Y39:$AI39)) | AK39: =IF(ISERROR(IF($AJ39="","",ROUND(($AJ39/$AJ$13)*$AK$13,2))),"",IF($AJ39="","",ROUND(($AJ39/$AJ$13)*$AK$13,2))) | AL39: =IF($AK39="","",ROUND($AK39*$AL$13,2)) | AN39: =IF(ISERROR(IF($AM39="","",ROUND(($AM39/$AM$13)*$AN$13,2))),"",IF($AM39="","",ROUND(($AM39/$AM$13)*$AN$13,2))) | AO39: =IF($AN39="","",ROUND($AN39*$AO$13,2)) | AP39: =IF(ISERROR(IF($AM39="","",ROUND(SUM($X39,$AL39,$AO39),2))),"",IF($AM39="","",ROUND(SUM($X39,$AL39,$AO39),2))) | AQ39: =IF(ISERROR(IF($AM39="","",VLOOKUP(AP39,TRANSMUTATION_TABLE,4,TRUE))),"",IF($AM39="","",VLOOKUP(AP39,TRANSMUTATION_TABLE,4,TRUE)))
V40: =IF(COUNT($F40:$U40)=0,"",SUM($F40:$U40)) | W40: =IF(ISERROR(IF($V40="","",ROUND(($V40/$V$13)*$W$13,2))),"",IF($V40="","",ROUND(($V40/$V$13)*$W$13,2))) | X40: =IF($W40="","",ROUND($W40*$X$13,2)) | AJ40: =IF(COUNT($Y40:$AI40)=0,"",SUM($Y40:$AI40)) | AK40: =IF(ISERROR(IF($AJ40="","",ROUND(($AJ40/$AJ$13)*$AK$13,2))),"",IF($AJ40="","",ROUND(($AJ40/$AJ$13)*$AK$13,2))) | AL40: =IF($AK40="","",ROUND($AK40*$AL$13,2)) | AN40: =IF(ISERROR(IF($AM40="","",ROUND(($AM40/$AM$13)*$AN$13,2))),"",IF($AM40="","",ROUND(($AM40/$AM$13)*$AN$13,2))) | AO40: =IF($AN40="","",ROUND($AN40*$AO$13,2)) | AP40: =IF(ISERROR(IF($AM40="","",ROUND(SUM($X40,$AL40,$AO40),2))),"",IF($AM40="","",ROUND(SUM($X40,$AL40,$AO40),2))) | AQ40: =IF(ISERROR(IF($AM40="","",VLOOKUP(AP40,TRANSMUTATION_TABLE,4,TRUE))),"",IF($AM40="","",VLOOKUP(AP40,TRANSMUTATION_TABLE,4,TRUE)))
V41: =IF(COUNT($F41:$U41)=0,"",SUM($F41:$U41)) | W41: =IF(ISERROR(IF($V41="","",ROUND(($V41/$V$13)*$W$13,2))),"",IF($V41="","",ROUND(($V41/$V$13)*$W$13,2))) | X41: =IF($W41="","",ROUND($W41*$X$13,2)) | AJ41: =IF(COUNT($Y41:$AI41)=0,"",SUM($Y41:$AI41)) | AK41: =IF(ISERROR(IF($AJ41="","",ROUND(($AJ41/$AJ$13)*$AK$13,2))),"",IF($AJ41="","",ROUND(($AJ41/$AJ$13)*$AK$13,2))) | AL41: =IF($AK41="","",ROUND($AK41*$AL$13,2)) | AN41: =IF(ISERROR(IF($AM41="","",ROUND(($AM41/$AM$13)*$AN$13,2))),"",IF($AM41="","",ROUND(($AM41/$AM$13)*$AN$13,2))) | AO41: =IF($AN41="","",ROUND($AN41*$AO$13,2)) | AP41: =IF(ISERROR(IF($AM41="","",ROUND(SUM($X41,$AL41,$AO41),2))),"",IF($AM41="","",ROUND(SUM($X41,$AL41,$AO41),2))) | AQ41: =IF(ISERROR(IF($AM41="","",VLOOKUP(AP41,TRANSMUTATION_TABLE,4,TRUE))),"",IF($AM41="","",VLOOKUP(AP41,TRANSMUTATION_TABLE,4,TRUE)))
V42: =IF(COUNT($F42:$U42)=0,"",SUM($F42:$U42)) | W42: =IF(ISERROR(IF($V42="","",ROUND(($V42/$V$13)*$W$13,2))),"",IF($V42="","",ROUND(($V42/$V$13)*$W$13,2))) | X42: =IF($W42="","",ROUND($W42*$X$13,2)) | AJ42: =IF(COUNT($Y42:$AI42)=0,"",SUM($Y42:$AI42)) | AK42: =IF(ISERROR(IF($AJ42="","",ROUND(($AJ42/$AJ$13)*$AK$13,2))),"",IF($AJ42="","",ROUND(($AJ42/$AJ$13)*$AK$13,2))) | AL42: =IF($AK42="","",ROUND($AK42*$AL$13,2)) | AN42: =IF(ISERROR(IF($AM42="","",ROUND(($AM42/$AM$13)*$AN$13,2))),"",IF($AM42="","",ROUND(($AM42/$AM$13)*$AN$13,2))) | AO42: =IF($AN42="","",ROUND($AN42*$AO$13,2)) | AP42: =IF(ISERROR(IF($AM42="","",ROUND(SUM($X42,$AL42,$AO42),2))),"",IF($AM42="","",ROUND(SUM($X42,$AL42,$AO42),2))) | AQ42: =IF(ISERROR(IF($AM42="","",VLOOKUP(AP42,TRANSMUTATION_TABLE,4,TRUE))),"",IF($AM42="","",VLOOKUP(AP42,TRANSMUTATION_TABLE,4,TRUE)))
V43: =IF(COUNT($F43:$U43)=0,"",SUM($F43:$U43)) | W43: =IF(ISERROR(IF($V43="","",ROUND(($V43/$V$13)*$W$13,2))),"",IF($V43="","",ROUND(($V43/$V$13)*$W$13,2))) | X43: =IF($W43="","",ROUND($W43*$X$13,2)) | AJ43: =IF(COUNT($Y43:$AI43)=0,"",SUM($Y43:$AI43)) | AK43: =IF(ISERROR(IF($AJ43="","",ROUND(($AJ43/$AJ$13)*$AK$13,2))),"",IF($AJ43="","",ROUND(($AJ43/$AJ$13)*$AK$13,2))) | AL43: =IF($AK43="","",ROUND($AK43*$AL$13,2)) | AN43: =IF(ISERROR(IF($AM43="","",ROUND(($AM43/$AM$13)*$AN$13,2))),"",IF($AM43="","",ROUND(($AM43/$AM$13)*$AN$13,2))) | AO43: =IF($AN43="","",ROUND($AN43*$AO$13,2)) | AP43: =IF(ISERROR(IF($AM43="","",ROUND(SUM($X43,$AL43,$AO43),2))),"",IF($AM43="","",ROUND(SUM($X43,$AL43,$AO43),2))) | AQ43: =IF(ISERROR(IF($AM43="","",VLOOKUP(AP43,TRANSMUTATION_TABLE,4,TRUE))),"",IF($AM43="","",VLOOKUP(AP43,TRANSMUTATION_TABLE,4,TRUE)))
V44: =IF(COUNT($F44:$U44)=0,"",SUM($F44:$U44)) | W44: =IF(ISERROR(IF($V44="","",ROUND(($V44/$V$13)*$W$13,2))),"",IF($V44="","",ROUND(($V44/$V$13)*$W$13,2))) | X44: =IF($W44="","",ROUND($W44*$X$13,2)) | AJ44: =IF(COUNT($Y44:$AI44)=0,"",SUM($Y44:$AI44)) | AK44: =IF(ISERROR(IF($AJ44="","",ROUND(($AJ44/$AJ$13)*$AK$13,2))),"",IF($AJ44="","",ROUND(($AJ44/$AJ$13)*$AK$13,2))) | AL44: =IF($AK44="","",ROUND($AK44*$AL$13,2)) | AN44: =IF(ISERROR(IF($AM44="","",ROUND(($AM44/$AM$13)*$AN$13,2))),"",IF($AM44="","",ROUND(($AM44/$AM$13)*$AN$13,2))) | AO44: =IF($AN44="","",ROUND($AN44*$AO$13,2)) | AP44: =IF(ISERROR(IF($AM44="","",ROUND(SUM($X44,$AL44,$AO44),2))),"",IF($AM44="","",ROUND(SUM($X44,$AL44,$AO44),2))) | AQ44: =IF(ISERROR(IF($AM44="","",VLOOKUP(AP44,TRANSMUTATION_TABLE,4,TRUE))),"",IF($AM44="","",VLOOKUP(AP44,TRANSMUTATION_TABLE,4,TRUE)))
...

Sheet SCIENCE_Q3
A1: Class Record
A3: (Pursuant to Deped Order 8 series of 2015)
C4: REGION | G4: NCR | U4: DIVISION | V4: PARAÑAQUE | Z4: DISTRICT | AH4: VII
B6: SCHOOL NAME | G6: PARAÑAQUE NATIONAL HIGH SCHOOL - BACLARAN | Z6: SCHOOL ID | AH6: 305426 | AK6: SCHOOL YEAR | AN6: 2025 - 2026
A8: THIRD QUARTER | F8: GRADE & SECTION: | O8: IX - | W8: TEACHER: | Y8: MRS. VANESSA G. LAS PIÑAS - TALENTO | AJ8: SUBJECT: | AL8: SCIENCE 9
B9: LEARNERS' NAMES | F9: WRITTEN WORKS (40%) | Y9: PERFORMANCE TASKS (40%) | AM9: QUARTERLY ASSESSMENT (20%) | AP9: Initial Grade | AQ9: Quarterly Grade
F10: SEATWORK | U10: Notebook | Y10: GROUP ACTIVITY | AI10: Recitation
F11: (Let's Recall, Let's Apply, Let's Analyze, Let's Try) | Y11: Let's Create | AM11: Periodic Test
F12: 1 | G12: 2 | H12: 3 | I12: 4 | J12: 5 | K12: 6 | L12: 7 | M12: 8 | N12: 9 | O12: 10 | P12: 11 | Q12: 12 | R12: 13 | S12: 14 | T12: 15 | U12: 3 | V12: Total | W12: PS | X12: WS | Y12: 1 | Z12: 2 | AA12: 3 | AB12: 4 | AC12: 5 | AD12: 6 | AE12: 7 | AF12: 8 | AG12: 9 | AH12: 10 | AI12: 3 | AJ12: Total | AK12: PS | AL12: WS | AM12: 3 | AN12: PS | AO12: WS
B13: HIGHEST POSSIBLE SCORE | V13: =IF(COUNT($F13:$U13)=0,"",SUM($F13:$U13)) | W13: 100 | X13: 0.4 | AJ13: =IF(COUNT($Y13:$AI13)=0,"",SUM($Y13:$AI13)) | AK13: 100 | AL13: 0.4 | AM13: 40 | AN13: 100 | AO13: 0.2
B14: MALE
A15: 1 | V15: =IF(COUNT($F15:$U15)=0,"",SUM($F15:$U15)) | W15: =IF(ISERROR(IF($V15="","",ROUND(($V15/$V$13)*$W$13,2))),"",IF($V15="","",ROUND(($V15/$V$13)*$W$13,2))) | X15: =IF($W15="","",ROUND($W15*$X$13,2)) | AJ15: =IF(COUNT($Y15:$AI15)=0,"",SUM($Y15:$AI15)) | AK15: =IF(ISERROR(IF($AJ15="","",ROUND(($AJ15/$AJ$13)*$AK$13,2))),"",IF($AJ15="","",ROUND(($AJ15/$AJ$13)*$AK$13,2))) | AL15: =IF($AK15="","",ROUND($AK15*$AL$13,2)) | AN15: =IF(ISERROR(IF($AM15="","",ROUND(($AM15/$AM$13)*$AN$13,2))),"",IF($AM15="","",ROUND(($AM15/$AM$13)*$AN$13,2))) | AO15: =IF($AN15="","",ROUND($AN15*$AO$13,2)) | AP15: =IF(ISERROR(IF($AM15="","",ROUND(SUM($X15,$AL15,$AO15),2))),"",IF($AM15="","",ROUND(SUM($X15,$AL15,$AO15),2))) | AQ15: =IF(ISERROR(IF($AM15="","",VLOOKUP(AP15,TRANSMUTATION_TABLE,4,TRUE))),"",IF($AM15="","",VLOOKUP(AP15,TRANSMUTATION_TABLE,4,TRUE))) | AT15: 60-69 | AU15: 78
A16: 2 | V16: =IF(COUNT($F16:$U16)=0,"",SUM($F16:$U16)) | W16: =IF(ISERROR(IF($V16="","",ROUND(($V16/$V$13)*$W$13,2))),"",IF($V16="","",ROUND(($V16/$V$13)*$W$13,2))) | X16: =IF($W16="","",ROUND($W16*$X$13,2)) | AJ16: =IF(COUNT($Y16:$AI16)=0,"",SUM($Y16:$AI16)) | AK16: =IF(ISERROR(IF($AJ16="","",ROUND(($AJ16/$AJ$13)*$AK$13,2))),"",IF($AJ16="","",ROUND(($AJ16/$AJ$13)*$AK$13,2))) | AL16: =IF($AK16="","",ROUND($AK16*$AL$13,2)) | AN16: =IF(ISERROR(IF($AM16="","",ROUND(($AM16/$AM$13)*$AN$13,2))),"",IF($AM16="","",ROUND(($AM16/$AM$13)*$AN$13,2))) | AO16: =IF($AN16="","",ROUND($AN16*$AO$13,2)) | AP16: =IF(ISERROR(IF($AM16="","",ROUND(SUM($X16,$AL16,$AO16),2))),"",IF($AM16="","",ROUND(SUM($X16,$AL16,$AO16),2))) | AQ16: =IF(ISERROR(IF($AM16="","",VLOOKUP(AP16,TRANSMUTATION_TABLE,4,TRUE))),"",IF($AM16="","",VLOOKUP(AP16,TRANSMUTATION_TABLE,4,TRUE))) | AT16: 70-74 | AU16: 79
A17: 3 | V17: =IF(COUNT($F17:$U17)=0,"",SUM($F17:$U17)) | W17: =IF(ISERROR(IF($V17="","",ROUND(($V17/$V$13)*$W$13,2))),"",IF($V17="","",ROUND(($V17/$V$13)*$W$13,2))) | X17: =IF($W17="","",ROUND($W17*$X$13,2)) | AJ17: =IF(COUNT($Y17:$AI17)=0,"",SUM($Y17:$AI17)) | AK17: =IF(ISERROR(IF($AJ17="","",ROUND(($AJ17/$AJ$13)*$AK$13,2))),"",IF($AJ17="","",ROUND(($AJ17/$AJ$13)*$AK$13,2))) | AL17: =IF($AK17="","",ROUND($AK17*$AL$13,2)) | AN17: =IF(ISERROR(IF($AM17="","",ROUND(($AM17/$AM$13)*$AN$13,2))),"",IF($AM17="","",ROUND(($AM17/$AM$13)*$AN$13,2))) | AO17: =IF($AN17="","",ROUND($AN17*$AO$13,2)) | AP17: =IF(ISERROR(IF($AM17="","",ROUND(SUM($X17,$AL17,$AO17),2))),"",IF($AM17="","",ROUND(SUM($X17,$AL17,$AO17),2))) | AQ17: =IF(ISERROR(IF($AM17="","",VLOOKUP(AP17,TRANSMUTATION_TABLE,4,TRUE))),"",IF($AM17="","",VLOOKUP(AP17,TRANSMUTATION_TABLE,4,TRUE))) | AT17: 75-79 | AU17: 80
A18: 4 | V18: =IF(COUNT($F18:$U18)=0,"",SUM($F18:$U18)) | W18: =IF(ISERROR(IF($V18="","",ROUND(($V18/$V$13)*$W$13,2))),"",IF($V18="","",ROUND(($V18/$V$13)*$W$13,2))) | X18: =IF($W18="","",ROUND($W18*$X$13,2)) | AJ18: =IF(COUNT($Y18:$AI18)=0,"",SUM($Y18:$AI18)) | AK18: =IF(ISERROR(IF($AJ18="","",ROUND(($AJ18/$AJ$13)*$AK$13,2))),"",IF($AJ18="","",ROUND(($AJ18/$AJ$13)*$AK$13,2))) | AL18: =IF($AK18="","",ROUND($AK18*$AL$13,2)) | AN18: =IF(ISERROR(IF($AM18="","",ROUND(($AM18/$AM$13)*$AN$13,2))),"",IF($AM18="","",ROUND(($AM18/$AM$13)*$AN$13,2))) | AO18: =IF($AN18="","",ROUND($AN18*$AO$13,2)) | AP18: =IF(ISERROR(IF($AM18="","",ROUND(SUM($X18,$AL18,$AO18),2))),"",IF($AM18="","",ROUND(SUM($X18,$AL18,$AO18),2))) | AQ18: =IF(ISERROR(IF($AM18="","",VLOOKUP(AP18,TRANSMUTATION_TABLE,4,TRUE))),"",IF($AM18="","",VLOOKUP(AP18,TRANSMUTATION_TABLE,4,TRUE))) | AT18: 80-84 | AU18: 85
A19: 5 | V19: =IF(COUNT($F19:$U19)=0,"",SUM($F19:$U19)) | W19: =IF(ISERROR(IF($V19="","",ROUND(($V19/$V$13)*$W$13,2))),"",IF($V19="","",ROUND(($V19/$V$13)*$W$13,2))) | X19: =IF($W19="","",ROUND($W19*$X$13,2)) | AJ19: =IF(COUNT($Y19:$AI19)=0,"",SUM($Y19:$AI19)) | AK19: =IF(ISERROR(IF($AJ19="","",ROUND(($AJ19/$AJ$13)*$AK$13,2))),"",IF($AJ19="","",ROUND(($AJ19/$AJ$13)*$AK$13,2))) | AL19: =IF($AK19="","",ROUND($AK19*$AL$13,2)) | AN19: =IF(ISERROR(IF($AM19="","",ROUND(($AM19/$AM$13)*$AN$13,2))),"",IF($AM19="","",ROUND(($AM19/$AM$13)*$AN$13,2))) | AO19: =IF($AN19="","",ROUND($AN19*$AO$13,2)) | AP19: =IF(ISERROR(IF($AM19="","",ROUND(SUM($X19,$AL19,$AO19),2))),"",IF($AM19="","",ROUND(SUM($X19,$AL19,$AO19),2))) | AQ19: =IF(ISERROR(IF($AM19="","",VLOOKUP(AP19,TRANSMUTATION_TABLE,4,TRUE))),"",IF($AM19="","",VLOOKUP(AP19,TRANSMUTATION_TABLE,4,TRUE))) | AT19: 85-88 | AU19: 89
A20: 6 | V20: =IF(COUNT($F20:$U20)=0,"",SUM($F20:$U20)) | W20: =IF(ISERROR(IF($V20="","",ROUND(($V20/$V$13)*$W$13,2))),"",IF($V20="","",ROUND(($V20/$V$13)*$W$13,2))) | X20: =IF($W20="","",ROUND($W20*$X$13,2)) | AJ20: =IF(COUNT($Y20:$AI20)=0,"",SUM($Y20:$AI20)) | AK20: =IF(ISERROR(IF($AJ20="","",ROUND(($AJ20/$AJ$13)*$AK$13,2))),"",IF($AJ20="","",ROUND(($AJ20/$AJ$13)*$AK$13,2))) | AL20: =IF($AK20="","",ROUND($AK20*$AL$13,2)) | AN20: =IF(ISERROR(IF($AM20="","",ROUND(($AM20/$AM$13)*$AN$13,2))),"",IF($AM20="","",ROUND(($AM20/$AM$13)*$AN$13,2))) | AO20: =IF($AN20="","",ROUND($AN20*$AO$13,2)) | AP20: =IF(ISERROR(IF($AM20="","",ROUND(SUM($X20,$AL20,$AO20),2))),"",IF($AM20="","",ROUND(SUM($X20,$AL20,$AO20),2))) | AQ20: =IF(ISERROR(IF($AM20="","",VLOOKUP(AP20,TRANSMUTATION_TABLE,4,TRUE))),"",IF($AM20="","",VLOOKUP(AP20,TRANSMUTATION_TABLE,4,TRUE))) | AT20: 89-91 | AU20: 92
A21: 7 | V21: =IF(COUNT($F21:$U21)=0,"",SUM($F21:$U21)) | W21: =IF(ISERROR(IF($V21="","",ROUND(($V21/$V$13)*$W$13,2))),"",IF($V21="","",ROUND(($V21/$V$13)*$W$13,2))) | X21: =IF($W21="","",ROUND($W21*$X$13,2)) | AJ21: =IF(COUNT($Y21:$AI21)=0,"",SUM($Y21:$AI21)) | AK21: =IF(ISERROR(IF($AJ21="","",ROUND(($AJ21/$AJ$13)*$AK$13,2))),"",IF($AJ21="","",ROUND(($AJ21/$AJ$13)*$AK$13,2))) | AL21: =IF($AK21="","",ROUND($AK21*$AL$13,2)) | AN21: =IF(ISERROR(IF($AM21="","",ROUND(($AM21/$AM$13)*$AN$13,2))),"",IF($AM21="","",ROUND(($AM21/$AM$13)*$AN$13,2))) | AO21: =IF($AN21="","",ROUND($AN21*$AO$13,2)) | AP21: =IF(ISERROR(IF($AM21="","",ROUND(SUM($X21,$AL21,$AO21),2))),"",IF($AM21="","",ROUND(SUM($X21,$AL21,$AO21),2))) | AQ21: =IF(ISERROR(IF($AM21="","",VLOOKUP(AP21,TRANSMUTATION_TABLE,4,TRUE))),"",IF($AM21="","",VLOOKUP(AP21,TRANSMUTATION_TABLE,4,TRUE)))
A22: 8 | V22: =IF(COUNT($F22:$U22)=0,"",SUM($F22:$U22)) | W22: =IF(ISERROR(IF($V22="","",ROUND(($V22/$V$13)*$W$13,2))),"",IF($V22="","",ROUND(($V22/$V$13)*$W$13,2))) | X22: =IF($W22="","",ROUND($W22*$X$13,2)) | AJ22: =IF(COUNT($Y22:$AI22)=0,"",SUM($Y22:$AI22)) | AK22: =IF(ISERROR(IF($AJ22="","",ROUND(($AJ22/$AJ$13)*$AK$13,2))),"",IF($AJ22="","",ROUND(($AJ22/$AJ$13)*$AK$13,2))) | AL22: =IF($AK22="","",ROUND($AK22*$AL$13,2)) | AN22: =IF(ISERROR(IF($AM22="","",ROUND(($AM22/$AM$13)*$AN$13,2))),"",IF($AM22="","",ROUND(($AM22/$AM$13)*$AN$13,2))) | AO22: =IF($AN22="","",ROUND($AN22*$AO$13,2)) | AP22: =IF(ISERROR(IF($AM22="","",ROUND(SUM($X22,$AL22,$AO22),2))),"",IF($AM22="","",ROUND(SUM($X22,$AL22,$AO22),2))) | AQ22: =IF(ISERROR(IF($AM22="","",VLOOKUP(AP22,TRANSMUTATION_TABLE,4,TRUE))),"",IF($AM22="","",VLOOKUP(AP22,TRANSMUTATION_TABLE,4,TRUE)))
A23: 9 | V23: =IF(COUNT($F23:$U23)=0,"",SUM($F23:$U23)) | W23: =IF(ISERROR(IF($V23="","",ROUND(($V23/$V$13)*$W$13,2))),"",IF($V23="","",ROUND(($V23/$V$13)*$W$13,2))) | X23: =IF($W23="","",ROUND($W23*$X$13,2)) | AJ23: =IF(COUNT($Y23:$AI23)=0,"",SUM($Y23:$AI23)) | AK23: =IF(ISERROR(IF($AJ23="","",ROUND(($AJ23/$AJ$13)*$AK$13,2))),"",IF($AJ23="","",ROUND(($AJ23/$AJ$13)*$AK$13,2))) | AL23: =IF($AK23="","",ROUND($AK23*$AL$13,2)) | AN23: =IF(ISERROR(IF($AM23="","",ROUND(($AM23/$AM$13)*$AN$13,2))),"",IF($AM23="","",ROUND(($AM23/$AM$13)*$AN$13,2))) | AO23: =IF($AN23="","",ROUND($AN23*$AO$13,2)) | AP23: =IF(ISERROR(IF($AM23="","",ROUND(SUM($X23,$AL23,$AO23),2))),"",IF($AM23="","",ROUND(SUM($X23,$AL23,$AO23),2))) | AQ23: =IF(ISERROR(IF($AM23="","",VLOOKUP(AP23,TRANSMUTATION_TABLE,4,TRUE))),"",IF($AM23="","",VLOOKUP(AP23,TRANSMUTATION_TABLE,4,TRUE)))
